W1114 04:13:08.725000 2318234 site-packages/torch/distributed/run.py:793] 
W1114 04:13:08.725000 2318234 site-packages/torch/distributed/run.py:793] *****************************************
W1114 04:13:08.725000 2318234 site-packages/torch/distributed/run.py:793] Setting OMP_NUM_THREADS environment variable for each process to be 1 in default, to avoid your system being overloaded, please further tune the variable for optimal performance in your application as needed. 
W1114 04:13:08.725000 2318234 site-packages/torch/distributed/run.py:793] *****************************************
flash_kv_decode is set to True
Using device=cuda
Loading model ...
GPTEnsemble(
  (tok_embeddings): Embedding(128256, 8192)
  (layers): ModuleList(
    (0-79): 80 x EnsembleTransformerBlock(
      semi_compiled = False
      (attention): Attention(
        (wqkv): Linear(in_features=8192, out_features=5120, bias=False)
        (wo): Linear(in_features=4096, out_features=8192, bias=False)
      )
      (feed_forward): FeedForward(
        (w1): Linear(in_features=8192, out_features=28672, bias=False)
        (w2): Linear(in_features=14336, out_features=8192, bias=False)
      )
      (ffn_norm): RMSNorm()
      (attention_norm): RMSNorm()
    )
  )
  (norm): RMSNorm()
  (output): Linear(in_features=8192, out_features=128256, bias=False)
)
Time to load model: 1.28 seconds
CUDA_GRAPH are activate
[rank0]: Traceback (most recent call last):
[rank0]:   File "/home/charlie/skip-residual/gpt-fast/benchmark.py", line 271, in get_cuda_graphs_for_prefill
[rank0]:     static_next_token = prefill(model, static_x.view(batch_size, -1), static_input_pos, **sampling_kwargs)
[rank0]:   File "/home/charlie/anaconda3/envs/gpt-fast/lib/python3.10/site-packages/torch/utils/_contextlib.py", line 116, in decorate_context
[rank0]:     return func(*args, **kwargs)
[rank0]:   File "/home/charlie/skip-residual/gpt-fast/benchmark.py", line 82, in prefill
[rank0]:     logits = model(x, input_pos)
[rank0]:   File "/home/charlie/anaconda3/envs/gpt-fast/lib/python3.10/site-packages/torch/nn/modules/module.py", line 1740, in _wrapped_call_impl
[rank0]:     return self._call_impl(*args, **kwargs)
[rank0]:   File "/home/charlie/anaconda3/envs/gpt-fast/lib/python3.10/site-packages/torch/nn/modules/module.py", line 1751, in _call_impl
[rank0]:     return forward_call(*args, **kwargs)
[rank0]:   File "/home/charlie/skip-residual/gpt-fast/gpt_fast/gpt_ensemble_TP.py", line 139, in forward
[rank0]:     x = layer(x, input_pos, freqs_cis, mask)
[rank0]:   File "/home/charlie/anaconda3/envs/gpt-fast/lib/python3.10/site-packages/torch/nn/modules/module.py", line 1740, in _wrapped_call_impl
[rank0]:     return self._call_impl(*args, **kwargs)
[rank0]:   File "/home/charlie/anaconda3/envs/gpt-fast/lib/python3.10/site-packages/torch/nn/modules/module.py", line 1751, in _call_impl
[rank0]:     return forward_call(*args, **kwargs)
[rank0]:   File "/home/charlie/skip-residual/gpt-fast/gpt_fast/gpt_ensemble_TP.py", line 214, in forward
[rank0]:     x = self.feed_forward(self.ffn_norm(x))
[rank0]:   File "/home/charlie/anaconda3/envs/gpt-fast/lib/python3.10/site-packages/torch/nn/modules/module.py", line 1740, in _wrapped_call_impl
[rank0]:     return self._call_impl(*args, **kwargs)
[rank0]:   File "/home/charlie/anaconda3/envs/gpt-fast/lib/python3.10/site-packages/torch/nn/modules/module.py", line 1751, in _call_impl
[rank0]:     return forward_call(*args, **kwargs)
[rank0]:   File "/home/charlie/skip-residual/gpt-fast/gpt_fast/utils.py", line 140, in forward
[rank0]:     y = self.w2(F.silu(g) * u)
[rank0]: torch.OutOfMemoryError: CUDA out of memory. Tried to allocate 112.00 MiB. GPU 0 has a total capacity of 79.33 GiB of which 43.44 MiB is free. Including non-PyTorch memory, this process has 79.28 GiB memory in use. Of the allocated memory 72.86 GiB is allocated by PyTorch, with 3.67 GiB allocated in private pools (e.g., CUDA Graphs), and 4.68 GiB is reserved by PyTorch but unallocated. If reserved but unallocated memory is large try setting PYTORCH_CUDA_ALLOC_CONF=expandable_segments:True to avoid fragmentation.  See documentation for Memory Management  (https://pytorch.org/docs/stable/notes/cuda.html#environment-variables)

[rank0]: During handling of the above exception, another exception occurred:

[rank0]: Traceback (most recent call last):
[rank0]:   File "/home/charlie/skip-residual/gpt-fast/benchmark.py", line 492, in <module>
[rank0]:     main(
[rank0]:   File "/home/charlie/skip-residual/gpt-fast/benchmark.py", line 360, in main
[rank0]:     prefill_graph, static_x, static_input_pos, static_next_token_prefill = get_cuda_graphs_for_prefill(
[rank0]:   File "/home/charlie/anaconda3/envs/gpt-fast/lib/python3.10/site-packages/torch/utils/_contextlib.py", line 116, in decorate_context
[rank0]:     return func(*args, **kwargs)
[rank0]:   File "/home/charlie/skip-residual/gpt-fast/benchmark.py", line 270, in get_cuda_graphs_for_prefill
[rank0]:     with torch.cuda.graph(g):
[rank0]:   File "/home/charlie/anaconda3/envs/gpt-fast/lib/python3.10/site-packages/torch/cuda/graphs.py", line 186, in __exit__
[rank0]:     self.cuda_graph.capture_end()
[rank0]:   File "/home/charlie/anaconda3/envs/gpt-fast/lib/python3.10/site-packages/torch/cuda/graphs.py", line 84, in capture_end
[rank0]:     super().capture_end()
[rank0]: RuntimeError: CUDA error: out of memory
[rank0]: CUDA kernel errors might be asynchronously reported at some other API call, so the stacktrace below might be incorrect.
[rank0]: For debugging consider passing CUDA_LAUNCH_BLOCKING=1
[rank0]: Compile with `TORCH_USE_CUDA_DSA` to enable device-side assertions.

[rank1]: Traceback (most recent call last):
[rank1]:   File "/home/charlie/skip-residual/gpt-fast/benchmark.py", line 271, in get_cuda_graphs_for_prefill
[rank1]:     static_next_token = prefill(model, static_x.view(batch_size, -1), static_input_pos, **sampling_kwargs)
[rank1]:   File "/home/charlie/anaconda3/envs/gpt-fast/lib/python3.10/site-packages/torch/utils/_contextlib.py", line 116, in decorate_context
[rank1]:     return func(*args, **kwargs)
[rank1]:   File "/home/charlie/skip-residual/gpt-fast/benchmark.py", line 82, in prefill
[rank1]:     logits = model(x, input_pos)
[rank1]:   File "/home/charlie/anaconda3/envs/gpt-fast/lib/python3.10/site-packages/torch/nn/modules/module.py", line 1740, in _wrapped_call_impl
[rank1]:     return self._call_impl(*args, **kwargs)
[rank1]:   File "/home/charlie/anaconda3/envs/gpt-fast/lib/python3.10/site-packages/torch/nn/modules/module.py", line 1751, in _call_impl
[rank1]:     return forward_call(*args, **kwargs)
[rank1]:   File "/home/charlie/skip-residual/gpt-fast/gpt_fast/gpt_ensemble_TP.py", line 139, in forward
[rank1]:     x = layer(x, input_pos, freqs_cis, mask)
[rank1]:   File "/home/charlie/anaconda3/envs/gpt-fast/lib/python3.10/site-packages/torch/nn/modules/module.py", line 1740, in _wrapped_call_impl
[rank1]:     return self._call_impl(*args, **kwargs)
[rank1]:   File "/home/charlie/anaconda3/envs/gpt-fast/lib/python3.10/site-packages/torch/nn/modules/module.py", line 1751, in _call_impl
[rank1]:     return forward_call(*args, **kwargs)
[rank1]:   File "/home/charlie/skip-residual/gpt-fast/gpt_fast/gpt_ensemble_TP.py", line 214, in forward
[rank1]:     x = self.feed_forward(self.ffn_norm(x))
[rank1]:   File "/home/charlie/anaconda3/envs/gpt-fast/lib/python3.10/site-packages/torch/nn/modules/module.py", line 1740, in _wrapped_call_impl
[rank1]:     return self._call_impl(*args, **kwargs)
[rank1]:   File "/home/charlie/anaconda3/envs/gpt-fast/lib/python3.10/site-packages/torch/nn/modules/module.py", line 1751, in _call_impl
[rank1]:     return forward_call(*args, **kwargs)
[rank1]:   File "/home/charlie/skip-residual/gpt-fast/gpt_fast/utils.py", line 140, in forward
[rank1]:     y = self.w2(F.silu(g) * u)
[rank1]: torch.OutOfMemoryError: CUDA out of memory. Tried to allocate 112.00 MiB. GPU 1 has a total capacity of 79.33 GiB of which 43.44 MiB is free. Including non-PyTorch memory, this process has 79.28 GiB memory in use. Of the allocated memory 72.86 GiB is allocated by PyTorch, with 3.67 GiB allocated in private pools (e.g., CUDA Graphs), and 4.68 GiB is reserved by PyTorch but unallocated. If reserved but unallocated memory is large try setting PYTORCH_CUDA_ALLOC_CONF=expandable_segments:True to avoid fragmentation.  See documentation for Memory Management  (https://pytorch.org/docs/stable/notes/cuda.html#environment-variables)

[rank1]: During handling of the above exception, another exception occurred:

[rank1]: Traceback (most recent call last):
[rank1]:   File "/home/charlie/skip-residual/gpt-fast/benchmark.py", line 492, in <module>
[rank1]:     main(
[rank1]:   File "/home/charlie/skip-residual/gpt-fast/benchmark.py", line 360, in main
[rank1]:     prefill_graph, static_x, static_input_pos, static_next_token_prefill = get_cuda_graphs_for_prefill(
[rank1]:   File "/home/charlie/anaconda3/envs/gpt-fast/lib/python3.10/site-packages/torch/utils/_contextlib.py", line 116, in decorate_context
[rank1]:     return func(*args, **kwargs)
[rank1]:   File "/home/charlie/skip-residual/gpt-fast/benchmark.py", line 270, in get_cuda_graphs_for_prefill
[rank1]:     with torch.cuda.graph(g):
[rank1]:   File "/home/charlie/anaconda3/envs/gpt-fast/lib/python3.10/site-packages/torch/cuda/graphs.py", line 186, in __exit__
[rank1]:     self.cuda_graph.capture_end()
[rank1]:   File "/home/charlie/anaconda3/envs/gpt-fast/lib/python3.10/site-packages/torch/cuda/graphs.py", line 84, in capture_end
[rank1]:     super().capture_end()
[rank1]: RuntimeError: CUDA error: out of memory
[rank1]: CUDA kernel errors might be asynchronously reported at some other API call, so the stacktrace below might be incorrect.
[rank1]: For debugging consider passing CUDA_LAUNCH_BLOCKING=1
[rank1]: Compile with `TORCH_USE_CUDA_DSA` to enable device-side assertions.

[rank0]:[W1114 04:13:17.330034390 ProcessGroupNCCL.cpp:1374] Warning: WARNING: process group has NOT been destroyed before we destruct ProcessGroupNCCL. On normal program exit, the application should call destroy_process_group to ensure that any pending NCCL operations have finished in this process. In rare cases this process can exit before this point and block the progress of another member of the process group. This constraint has always been present,  but this warning has only been added since PyTorch 2.4 (function operator())
W1114 04:13:18.905000 2318234 site-packages/torch/distributed/elastic/multiprocessing/api.py:897] Sending process 2318305 closing signal SIGTERM
E1114 04:13:19.072000 2318234 site-packages/torch/distributed/elastic/multiprocessing/api.py:869] failed (exitcode: 1) local_rank: 0 (pid: 2318304) of binary: /home/charlie/anaconda3/envs/gpt-fast/bin/python
Traceback (most recent call last):
  File "/home/charlie/anaconda3/envs/gpt-fast/bin/torchrun", line 8, in <module>
    sys.exit(main())
  File "/home/charlie/anaconda3/envs/gpt-fast/lib/python3.10/site-packages/torch/distributed/elastic/multiprocessing/errors/__init__.py", line 355, in wrapper
    return f(*args, **kwargs)
  File "/home/charlie/anaconda3/envs/gpt-fast/lib/python3.10/site-packages/torch/distributed/run.py", line 919, in main
    run(args)
  File "/home/charlie/anaconda3/envs/gpt-fast/lib/python3.10/site-packages/torch/distributed/run.py", line 910, in run
    elastic_launch(
  File "/home/charlie/anaconda3/envs/gpt-fast/lib/python3.10/site-packages/torch/distributed/launcher/api.py", line 138, in __call__
    return launch_agent(self._config, self._entrypoint, list(args))
  File "/home/charlie/anaconda3/envs/gpt-fast/lib/python3.10/site-packages/torch/distributed/launcher/api.py", line 269, in launch_agent
    raise ChildFailedError(
torch.distributed.elastic.multiprocessing.errors.ChildFailedError: 
============================================================
benchmark.py FAILED
------------------------------------------------------------
Failures:
  <NO_OTHER_FAILURES>
------------------------------------------------------------
Root Cause (first observed failure):
[0]:
  time      : 2024-11-14_04:13:18
  host      : mk-xii-11.cloud.together.ai
  rank      : 0 (local_rank: 0)
  exitcode  : 1 (pid: 2318304)
  error_file: <N/A>
  traceback : To enable traceback see: https://pytorch.org/docs/stable/elastic/errors.html
============================================================
