W0920 09:01:14.686000 22769893771072 torch/distributed/run.py:779] 
W0920 09:01:14.686000 22769893771072 torch/distributed/run.py:779] *****************************************
W0920 09:01:14.686000 22769893771072 torch/distributed/run.py:779] Setting OMP_NUM_THREADS environment variable for each process to be 1 in default, to avoid your system being overloaded, please further tune the variable for optimal performance in your application as needed. 
W0920 09:01:14.686000 22769893771072 torch/distributed/run.py:779] *****************************************
flash_kv_decode is set to True
Using device=cuda
Loading model ...
GPTDense(
  (tok_embeddings): Embedding(128256, 4096)
  (layers): ModuleList(
    (0-31): 32 x DenseTransformerBlock(
      semi_compiled = False
      (attention): Attention(
        (wqkv): Linear(in_features=4096, out_features=3072, bias=False)
        (wo): Linear(in_features=2048, out_features=4096, bias=False)
      )
      (feed_forward): FeedForward(
        (w1): Linear(in_features=4096, out_features=14336, bias=False)
        (w2): Linear(in_features=7168, out_features=4096, bias=False)
      )
      (ffn_norm): RMSNorm()
      (attention_norm): RMSNorm()
    )
  )
  (norm): RMSNorm()
  (output): Linear(in_features=4096, out_features=128256, bias=False)
)
Time to load model: 0.91 seconds
/home/charlie/anaconda3/envs/gpt-fast/lib/python3.10/contextlib.py:103: FutureWarning: `torch.backends.cuda.sdp_kernel()` is deprecated. In the future, this context manager will be removed. Please see `torch.nn.attention.sdpa_kernel()` for the new context manager, with updated signature.
  self.gen = func(*args, **kwds)
/home/charlie/anaconda3/envs/gpt-fast/lib/python3.10/contextlib.py:103: FutureWarning: `torch.backends.cuda.sdp_kernel()` is deprecated. In the future, this context manager will be removed. Please see `torch.nn.attention.sdpa_kernel()` for the new context manager, with updated signature.
  self.gen = func(*args, **kwds)
Prefill latency: 3.320662660524249 sec
[rank1]: Traceback (most recent call last):
[rank1]:   File "/home/charlie/skip-residual/gpt-fast/benchmark.py", line 518, in <module>
[rank1]:     main(
[rank1]:   File "/home/charlie/skip-residual/gpt-fast/benchmark.py", line 448, in main
[rank1]:     y, decode_latency, prefill_latency = generate(
[rank1]:   File "/home/charlie/anaconda3/envs/gpt-fast/lib/python3.10/site-packages/torch/utils/_contextlib.py", line 116, in decorate_context
[rank1]:     return func(*args, **kwargs)
[rank1]:   File "/home/charlie/skip-residual/gpt-fast/benchmark.py", line 157, in generate
[rank1]:     generated_tokens, _ = decode_n_tokens(model, next_token.view(batch_size, -1), input_pos, max_new_tokens - 1, use_flash_attention=use_flash_attention, callback=callback, **sampling_kwargs)
[rank1]:   File "/home/charlie/anaconda3/envs/gpt-fast/lib/python3.10/site-packages/torch/utils/_contextlib.py", line 116, in decorate_context
[rank1]:     return func(*args, **kwargs)
[rank1]:   File "/home/charlie/skip-residual/gpt-fast/benchmark.py", line 105, in decode_n_tokens
[rank1]:     next_token, next_prob = decode_one_token(
[rank1]:   File "/home/charlie/skip-residual/gpt-fast/benchmark.py", line 85, in decode_one_token
[rank1]:     logits = model(x, input_pos)
[rank1]:   File "/home/charlie/anaconda3/envs/gpt-fast/lib/python3.10/site-packages/torch/nn/modules/module.py", line 1553, in _wrapped_call_impl
[rank1]:     return self._call_impl(*args, **kwargs)
[rank1]:   File "/home/charlie/anaconda3/envs/gpt-fast/lib/python3.10/site-packages/torch/nn/modules/module.py", line 1562, in _call_impl
[rank1]:     return forward_call(*args, **kwargs)
[rank1]:   File "/home/charlie/skip-residual/gpt-fast/gpt_fast/gpt_dense_TP.py", line 124, in forward
[rank1]:     x = layer(x, input_pos, freqs_cis, mask)
[rank1]:   File "/home/charlie/anaconda3/envs/gpt-fast/lib/python3.10/site-packages/torch/nn/modules/module.py", line 1553, in _wrapped_call_impl
[rank1]:     return self._call_impl(*args, **kwargs)
[rank1]:   File "/home/charlie/anaconda3/envs/gpt-fast/lib/python3.10/site-packages/torch/nn/modules/module.py", line 1562, in _call_impl
[rank1]:     return forward_call(*args, **kwargs)
[rank1]:   File "/home/charlie/skip-residual/gpt-fast/gpt_fast/gpt_dense_TP.py", line 173, in forward
[rank1]:     x = x + all_reduce_func(self.feed_forward(self.ffn_norm(x)), clone=False)[0]
[rank1]:   File "/home/charlie/anaconda3/envs/gpt-fast/lib/python3.10/site-packages/torch/nn/modules/module.py", line 1553, in _wrapped_call_impl
[rank1]:     return self._call_impl(*args, **kwargs)
[rank1]:   File "/home/charlie/anaconda3/envs/gpt-fast/lib/python3.10/site-packages/torch/nn/modules/module.py", line 1562, in _call_impl
[rank1]:     return forward_call(*args, **kwargs)
[rank1]:   File "/home/charlie/skip-residual/gpt-fast/gpt_fast/utils.py", line 140, in forward
[rank1]:     y = self.w2(F.silu(g) * u)
[rank1]: RuntimeError: CUDA error: an illegal memory access was encountered
[rank1]: CUDA kernel errors might be asynchronously reported at some other API call, so the stacktrace below might be incorrect.
[rank1]: For debugging consider passing CUDA_LAUNCH_BLOCKING=1
[rank1]: Compile with `TORCH_USE_CUDA_DSA` to enable device-side assertions.

[rank1]:[E920 09:01:25.222175588 ProcessGroupNCCL.cpp:1515] [PG 0 (default_pg) Rank 1] Process group watchdog thread terminated with exception: CUDA error: an illegal memory access was encountered
CUDA kernel errors might be asynchronously reported at some other API call, so the stacktrace below might be incorrect.
For debugging consider passing CUDA_LAUNCH_BLOCKING=1
Compile with `TORCH_USE_CUDA_DSA` to enable device-side assertions.

Exception raised from c10_cuda_check_implementation at ../c10/cuda/CUDAException.cpp:43 (most recent call first):
frame #0: c10::Error::Error(c10::SourceLocation, std::string) + 0x96 (0x14dd83ccbf86 in /home/charlie/anaconda3/envs/gpt-fast/lib/python3.10/site-packages/torch/lib/libc10.so)
frame #1: c10::detail::torchCheckFail(char const*, char const*, unsigned int, std::string const&) + 0x64 (0x14dd83c7ad10 in /home/charlie/anaconda3/envs/gpt-fast/lib/python3.10/site-packages/torch/lib/libc10.so)
frame #2: c10::cuda::c10_cuda_check_implementation(int, char const*, char const*, int, bool) + 0x118 (0x14dd83da6f08 in /home/charlie/anaconda3/envs/gpt-fast/lib/python3.10/site-packages/torch/lib/libc10_cuda.so)
frame #3: c10d::ProcessGroupNCCL::WorkNCCL::finishedGPUExecutionInternal() const + 0x56 (0x14dd363c5406 in /home/charlie/anaconda3/envs/gpt-fast/lib/python3.10/site-packages/torch/lib/libtorch_cuda.so)
frame #4: c10d::ProcessGroupNCCL::WorkNCCL::isCompleted() + 0xa0 (0x14dd363ca620 in /home/charlie/anaconda3/envs/gpt-fast/lib/python3.10/site-packages/torch/lib/libtorch_cuda.so)
frame #5: c10d::ProcessGroupNCCL::watchdogHandler() + 0x1da (0x14dd363d12da in /home/charlie/anaconda3/envs/gpt-fast/lib/python3.10/site-packages/torch/lib/libtorch_cuda.so)
frame #6: c10d::ProcessGroupNCCL::ncclCommWatchdog() + 0x10c (0x14dd363d371c in /home/charlie/anaconda3/envs/gpt-fast/lib/python3.10/site-packages/torch/lib/libtorch_cuda.so)
frame #7: <unknown function> + 0xd3b75 (0x14dd840f0b75 in /home/charlie/anaconda3/envs/gpt-fast/bin/../lib/libstdc++.so.6)
frame #8: <unknown function> + 0x94ac3 (0x14dd85145ac3 in /lib/x86_64-linux-gnu/libc.so.6)
frame #9: <unknown function> + 0x126850 (0x14dd851d7850 in /lib/x86_64-linux-gnu/libc.so.6)

terminate called after throwing an instance of 'c10::DistBackendError'
  what():  [PG 0 (default_pg) Rank 1] Process group watchdog thread terminated with exception: CUDA error: an illegal memory access was encountered
CUDA kernel errors might be asynchronously reported at some other API call, so the stacktrace below might be incorrect.
For debugging consider passing CUDA_LAUNCH_BLOCKING=1
Compile with `TORCH_USE_CUDA_DSA` to enable device-side assertions.

Exception raised from c10_cuda_check_implementation at ../c10/cuda/CUDAException.cpp:43 (most recent call first):
frame #0: c10::Error::Error(c10::SourceLocation, std::string) + 0x96 (0x14dd83ccbf86 in /home/charlie/anaconda3/envs/gpt-fast/lib/python3.10/site-packages/torch/lib/libc10.so)
frame #1: c10::detail::torchCheckFail(char const*, char const*, unsigned int, std::string const&) + 0x64 (0x14dd83c7ad10 in /home/charlie/anaconda3/envs/gpt-fast/lib/python3.10/site-packages/torch/lib/libc10.so)
frame #2: c10::cuda::c10_cuda_check_implementation(int, char const*, char const*, int, bool) + 0x118 (0x14dd83da6f08 in /home/charlie/anaconda3/envs/gpt-fast/lib/python3.10/site-packages/torch/lib/libc10_cuda.so)
frame #3: c10d::ProcessGroupNCCL::WorkNCCL::finishedGPUExecutionInternal() const + 0x56 (0x14dd363c5406 in /home/charlie/anaconda3/envs/gpt-fast/lib/python3.10/site-packages/torch/lib/libtorch_cuda.so)
frame #4: c10d::ProcessGroupNCCL::WorkNCCL::isCompleted() + 0xa0 (0x14dd363ca620 in /home/charlie/anaconda3/envs/gpt-fast/lib/python3.10/site-packages/torch/lib/libtorch_cuda.so)
frame #5: c10d::ProcessGroupNCCL::watchdogHandler() + 0x1da (0x14dd363d12da in /home/charlie/anaconda3/envs/gpt-fast/lib/python3.10/site-packages/torch/lib/libtorch_cuda.so)
frame #6: c10d::ProcessGroupNCCL::ncclCommWatchdog() + 0x10c (0x14dd363d371c in /home/charlie/anaconda3/envs/gpt-fast/lib/python3.10/site-packages/torch/lib/libtorch_cuda.so)
frame #7: <unknown function> + 0xd3b75 (0x14dd840f0b75 in /home/charlie/anaconda3/envs/gpt-fast/bin/../lib/libstdc++.so.6)
frame #8: <unknown function> + 0x94ac3 (0x14dd85145ac3 in /lib/x86_64-linux-gnu/libc.so.6)
frame #9: <unknown function> + 0x126850 (0x14dd851d7850 in /lib/x86_64-linux-gnu/libc.so.6)

Exception raised from ncclCommWatchdog at ../torch/csrc/distributed/c10d/ProcessGroupNCCL.cpp:1521 (most recent call first):
frame #0: c10::Error::Error(c10::SourceLocation, std::string) + 0x96 (0x14dd83ccbf86 in /home/charlie/anaconda3/envs/gpt-fast/lib/python3.10/site-packages/torch/lib/libc10.so)
frame #1: <unknown function> + 0xe5aa84 (0x14dd3605ca84 in /home/charlie/anaconda3/envs/gpt-fast/lib/python3.10/site-packages/torch/lib/libtorch_cuda.so)
frame #2: <unknown function> + 0xd3b75 (0x14dd840f0b75 in /home/charlie/anaconda3/envs/gpt-fast/bin/../lib/libstdc++.so.6)
frame #3: <unknown function> + 0x94ac3 (0x14dd85145ac3 in /lib/x86_64-linux-gnu/libc.so.6)
frame #4: <unknown function> + 0x126850 (0x14dd851d7850 in /lib/x86_64-linux-gnu/libc.so.6)

[rank0]:[E920 09:01:25.259392430 ProcessGroupNCCL.cpp:1515] [PG 0 (default_pg) Rank 0] Process group watchdog thread terminated with exception: CUDA error: an illegal memory access was encountered
CUDA kernel errors might be asynchronously reported at some other API call, so the stacktrace below might be incorrect.
For debugging consider passing CUDA_LAUNCH_BLOCKING=1
Compile with `TORCH_USE_CUDA_DSA` to enable device-side assertions.

Exception raised from c10_cuda_check_implementation at ../c10/cuda/CUDAException.cpp:43 (most recent call first):
frame #0: c10::Error::Error(c10::SourceLocation, std::string) + 0x96 (0x14caeb977f86 in /home/charlie/anaconda3/envs/gpt-fast/lib/python3.10/site-packages/torch/lib/libc10.so)
frame #1: c10::detail::torchCheckFail(char const*, char const*, unsigned int, std::string const&) + 0x64 (0x14caeb926d10 in /home/charlie/anaconda3/envs/gpt-fast/lib/python3.10/site-packages/torch/lib/libc10.so)
frame #2: c10::cuda::c10_cuda_check_implementation(int, char const*, char const*, int, bool) + 0x118 (0x14caec110f08 in /home/charlie/anaconda3/envs/gpt-fast/lib/python3.10/site-packages/torch/lib/libc10_cuda.so)
frame #3: c10d::ProcessGroupNCCL::WorkNCCL::finishedGPUExecutionInternal() const + 0x56 (0x14ca9dfc5406 in /home/charlie/anaconda3/envs/gpt-fast/lib/python3.10/site-packages/torch/lib/libtorch_cuda.so)
frame #4: c10d::ProcessGroupNCCL::WorkNCCL::isCompleted() + 0xa0 (0x14ca9dfca620 in /home/charlie/anaconda3/envs/gpt-fast/lib/python3.10/site-packages/torch/lib/libtorch_cuda.so)
frame #5: c10d::ProcessGroupNCCL::watchdogHandler() + 0x1da (0x14ca9dfd12da in /home/charlie/anaconda3/envs/gpt-fast/lib/python3.10/site-packages/torch/lib/libtorch_cuda.so)
frame #6: c10d::ProcessGroupNCCL::ncclCommWatchdog() + 0x10c (0x14ca9dfd371c in /home/charlie/anaconda3/envs/gpt-fast/lib/python3.10/site-packages/torch/lib/libtorch_cuda.so)
frame #7: <unknown function> + 0xd3b75 (0x14caebcf0b75 in /home/charlie/anaconda3/envs/gpt-fast/bin/../lib/libstdc++.so.6)
frame #8: <unknown function> + 0x94ac3 (0x14caece03ac3 in /lib/x86_64-linux-gnu/libc.so.6)
frame #9: <unknown function> + 0x126850 (0x14caece95850 in /lib/x86_64-linux-gnu/libc.so.6)

terminate called after throwing an instance of 'c10::DistBackendError'
  what():  [PG 0 (default_pg) Rank 0] Process group watchdog thread terminated with exception: CUDA error: an illegal memory access was encountered
CUDA kernel errors might be asynchronously reported at some other API call, so the stacktrace below might be incorrect.
For debugging consider passing CUDA_LAUNCH_BLOCKING=1
Compile with `TORCH_USE_CUDA_DSA` to enable device-side assertions.

Exception raised from c10_cuda_check_implementation at ../c10/cuda/CUDAException.cpp:43 (most recent call first):
frame #0: c10::Error::Error(c10::SourceLocation, std::string) + 0x96 (0x14caeb977f86 in /home/charlie/anaconda3/envs/gpt-fast/lib/python3.10/site-packages/torch/lib/libc10.so)
frame #1: c10::detail::torchCheckFail(char const*, char const*, unsigned int, std::string const&) + 0x64 (0x14caeb926d10 in /home/charlie/anaconda3/envs/gpt-fast/lib/python3.10/site-packages/torch/lib/libc10.so)
frame #2: c10::cuda::c10_cuda_check_implementation(int, char const*, char const*, int, bool) + 0x118 (0x14caec110f08 in /home/charlie/anaconda3/envs/gpt-fast/lib/python3.10/site-packages/torch/lib/libc10_cuda.so)
frame #3: c10d::ProcessGroupNCCL::WorkNCCL::finishedGPUExecutionInternal() const + 0x56 (0x14ca9dfc5406 in /home/charlie/anaconda3/envs/gpt-fast/lib/python3.10/site-packages/torch/lib/libtorch_cuda.so)
frame #4: c10d::ProcessGroupNCCL::WorkNCCL::isCompleted() + 0xa0 (0x14ca9dfca620 in /home/charlie/anaconda3/envs/gpt-fast/lib/python3.10/site-packages/torch/lib/libtorch_cuda.so)
frame #5: c10d::ProcessGroupNCCL::watchdogHandler() + 0x1da (0x14ca9dfd12da in /home/charlie/anaconda3/envs/gpt-fast/lib/python3.10/site-packages/torch/lib/libtorch_cuda.so)
frame #6: c10d::ProcessGroupNCCL::ncclCommWatchdog() + 0x10c (0x14ca9dfd371c in /home/charlie/anaconda3/envs/gpt-fast/lib/python3.10/site-packages/torch/lib/libtorch_cuda.so)
frame #7: <unknown function> + 0xd3b75 (0x14caebcf0b75 in /home/charlie/anaconda3/envs/gpt-fast/bin/../lib/libstdc++.so.6)
frame #8: <unknown function> + 0x94ac3 (0x14caece03ac3 in /lib/x86_64-linux-gnu/libc.so.6)
frame #9: <unknown function> + 0x126850 (0x14caece95850 in /lib/x86_64-linux-gnu/libc.so.6)

Exception raised from ncclCommWatchdog at ../torch/csrc/distributed/c10d/ProcessGroupNCCL.cpp:1521 (most recent call first):
frame #0: c10::Error::Error(c10::SourceLocation, std::string) + 0x96 (0x14caeb977f86 in /home/charlie/anaconda3/envs/gpt-fast/lib/python3.10/site-packages/torch/lib/libc10.so)
frame #1: <unknown function> + 0xe5aa84 (0x14ca9dc5ca84 in /home/charlie/anaconda3/envs/gpt-fast/lib/python3.10/site-packages/torch/lib/libtorch_cuda.so)
frame #2: <unknown function> + 0xd3b75 (0x14caebcf0b75 in /home/charlie/anaconda3/envs/gpt-fast/bin/../lib/libstdc++.so.6)
frame #3: <unknown function> + 0x94ac3 (0x14caece03ac3 in /lib/x86_64-linux-gnu/libc.so.6)
frame #4: <unknown function> + 0x126850 (0x14caece95850 in /lib/x86_64-linux-gnu/libc.so.6)

W0920 09:01:25.733000 22769893771072 torch/distributed/elastic/multiprocessing/api.py:858] Sending process 962718 closing signal SIGTERM
E0920 09:01:25.847000 22769893771072 torch/distributed/elastic/multiprocessing/api.py:833] failed (exitcode: -6) local_rank: 1 (pid: 962719) of binary: /home/charlie/anaconda3/envs/gpt-fast/bin/python
Traceback (most recent call last):
  File "/home/charlie/anaconda3/envs/gpt-fast/bin/torchrun", line 8, in <module>
    sys.exit(main())
  File "/home/charlie/anaconda3/envs/gpt-fast/lib/python3.10/site-packages/torch/distributed/elastic/multiprocessing/errors/__init__.py", line 348, in wrapper
    return f(*args, **kwargs)
  File "/home/charlie/anaconda3/envs/gpt-fast/lib/python3.10/site-packages/torch/distributed/run.py", line 901, in main
    run(args)
  File "/home/charlie/anaconda3/envs/gpt-fast/lib/python3.10/site-packages/torch/distributed/run.py", line 892, in run
    elastic_launch(
  File "/home/charlie/anaconda3/envs/gpt-fast/lib/python3.10/site-packages/torch/distributed/launcher/api.py", line 133, in __call__
    return launch_agent(self._config, self._entrypoint, list(args))
  File "/home/charlie/anaconda3/envs/gpt-fast/lib/python3.10/site-packages/torch/distributed/launcher/api.py", line 264, in launch_agent
    raise ChildFailedError(
torch.distributed.elastic.multiprocessing.errors.ChildFailedError: 
=======================================================
benchmark.py FAILED
-------------------------------------------------------
Failures:
  <NO_OTHER_FAILURES>
-------------------------------------------------------
Root Cause (first observed failure):
[0]:
  time      : 2024-09-20_09:01:25
  host      : mk-xii-15.cloud.together.ai
  rank      : 1 (local_rank: 1)
  exitcode  : -6 (pid: 962719)
  error_file: <N/A>
  traceback : Signal 6 (SIGABRT) received by PID 962719
=======================================================
