W0920 09:13:59.866000 22940906227520 torch/distributed/run.py:779] 
W0920 09:13:59.866000 22940906227520 torch/distributed/run.py:779] *****************************************
W0920 09:13:59.866000 22940906227520 torch/distributed/run.py:779] Setting OMP_NUM_THREADS environment variable for each process to be 1 in default, to avoid your system being overloaded, please further tune the variable for optimal performance in your application as needed. 
W0920 09:13:59.866000 22940906227520 torch/distributed/run.py:779] *****************************************
flash_kv_decode is set to True
Using device=cuda
Loading model ...
GPTDense(
  (tok_embeddings): Embedding(128256, 4096)
  (layers): ModuleList(
    (0-31): 32 x DenseTransformerBlock(
      semi_compiled = False
      (attention): Attention(
        (wqkv): Linear(in_features=4096, out_features=768, bias=False)
        (wo): Linear(in_features=512, out_features=4096, bias=False)
      )
      (feed_forward): FeedForward(
        (w1): Linear(in_features=4096, out_features=3584, bias=False)
        (w2): Linear(in_features=1792, out_features=4096, bias=False)
      )
      (ffn_norm): RMSNorm()
      (attention_norm): RMSNorm()
    )
  )
  (norm): RMSNorm()
  (output): Linear(in_features=4096, out_features=128256, bias=False)
)
Time to load model: 1.07 seconds
/home/charlie/anaconda3/envs/gpt-fast/lib/python3.10/contextlib.py:103: FutureWarning: `torch.backends.cuda.sdp_kernel()` is deprecated. In the future, this context manager will be removed. Please see `torch.nn.attention.sdpa_kernel()` for the new context manager, with updated signature.
  self.gen = func(*args, **kwds)
/home/charlie/anaconda3/envs/gpt-fast/lib/python3.10/contextlib.py:103: FutureWarning: `torch.backends.cuda.sdp_kernel()` is deprecated. In the future, this context manager will be removed. Please see `torch.nn.attention.sdpa_kernel()` for the new context manager, with updated signature.
  self.gen = func(*args, **kwds)
/home/charlie/anaconda3/envs/gpt-fast/lib/python3.10/contextlib.py:103: FutureWarning: `torch.backends.cuda.sdp_kernel()` is deprecated. In the future, this context manager will be removed. Please see `torch.nn.attention.sdpa_kernel()` for the new context manager, with updated signature.
  self.gen = func(*args, **kwds)
/home/charlie/anaconda3/envs/gpt-fast/lib/python3.10/contextlib.py:103: FutureWarning: `torch.backends.cuda.sdp_kernel()` is deprecated. In the future, this context manager will be removed. Please see `torch.nn.attention.sdpa_kernel()` for the new context manager, with updated signature.
  self.gen = func(*args, **kwds)
/home/charlie/anaconda3/envs/gpt-fast/lib/python3.10/contextlib.py:103: FutureWarning: `torch.backends.cuda.sdp_kernel()` is deprecated. In the future, this context manager will be removed. Please see `torch.nn.attention.sdpa_kernel()` for the new context manager, with updated signature.
  self.gen = func(*args, **kwds)
/home/charlie/anaconda3/envs/gpt-fast/lib/python3.10/contextlib.py:103: FutureWarning: `torch.backends.cuda.sdp_kernel()` is deprecated. In the future, this context manager will be removed. Please see `torch.nn.attention.sdpa_kernel()` for the new context manager, with updated signature.
  self.gen = func(*args, **kwds)
/home/charlie/anaconda3/envs/gpt-fast/lib/python3.10/contextlib.py:103: FutureWarning: `torch.backends.cuda.sdp_kernel()` is deprecated. In the future, this context manager will be removed. Please see `torch.nn.attention.sdpa_kernel()` for the new context manager, with updated signature.
  self.gen = func(*args, **kwds)
/home/charlie/anaconda3/envs/gpt-fast/lib/python3.10/contextlib.py:103: FutureWarning: `torch.backends.cuda.sdp_kernel()` is deprecated. In the future, this context manager will be removed. Please see `torch.nn.attention.sdpa_kernel()` for the new context manager, with updated signature.
  self.gen = func(*args, **kwds)
Prefill latency: 12.192897278815508 sec
[rank4]:[E920 09:14:24.529148046 ProcessGroupNCCL.cpp:1515] [PG 0 (default_pg) Rank 4] Process group watchdog thread terminated with exception: CUDA error: an illegal memory access was encountered
CUDA kernel errors might be asynchronously reported at some other API call, so the stacktrace below might be incorrect.
For debugging consider passing CUDA_LAUNCH_BLOCKING=1
Compile with `TORCH_USE_CUDA_DSA` to enable device-side assertions.

Exception raised from c10_cuda_check_implementation at ../c10/cuda/CUDAException.cpp:43 (most recent call first):
frame #0: c10::Error::Error(c10::SourceLocation, std::string) + 0x96 (0x14b159ecbf86 in /home/charlie/anaconda3/envs/gpt-fast/lib/python3.10/site-packages/torch/lib/libc10.so)
frame #1: c10::detail::torchCheckFail(char const*, char const*, unsigned int, std::string const&) + 0x64 (0x14b159e7ad10 in /home/charlie/anaconda3/envs/gpt-fast/lib/python3.10/site-packages/torch/lib/libc10.so)
frame #2: c10::cuda::c10_cuda_check_implementation(int, char const*, char const*, int, bool) + 0x118 (0x14b159fa6f08 in /home/charlie/anaconda3/envs/gpt-fast/lib/python3.10/site-packages/torch/lib/libc10_cuda.so)
frame #3: c10d::ProcessGroupNCCL::WorkNCCL::finishedGPUExecutionInternal() const + 0x56 (0x14b10c5c5406 in /home/charlie/anaconda3/envs/gpt-fast/lib/python3.10/site-packages/torch/lib/libtorch_cuda.so)
frame #4: c10d::ProcessGroupNCCL::WorkNCCL::isCompleted() + 0xa0 (0x14b10c5ca620 in /home/charlie/anaconda3/envs/gpt-fast/lib/python3.10/site-packages/torch/lib/libtorch_cuda.so)
frame #5: c10d::ProcessGroupNCCL::watchdogHandler() + 0x1da (0x14b10c5d12da in /home/charlie/anaconda3/envs/gpt-fast/lib/python3.10/site-packages/torch/lib/libtorch_cuda.so)
frame #6: c10d::ProcessGroupNCCL::ncclCommWatchdog() + 0x10c (0x14b10c5d371c in /home/charlie/anaconda3/envs/gpt-fast/lib/python3.10/site-packages/torch/lib/libtorch_cuda.so)
frame #7: <unknown function> + 0xd3b75 (0x14b15a2f0b75 in /home/charlie/anaconda3/envs/gpt-fast/bin/../lib/libstdc++.so.6)
frame #8: <unknown function> + 0x94ac3 (0x14b15b38aac3 in /lib/x86_64-linux-gnu/libc.so.6)
frame #9: <unknown function> + 0x126850 (0x14b15b41c850 in /lib/x86_64-linux-gnu/libc.so.6)

terminate called after throwing an instance of 'c10::DistBackendError'
  what():  [PG 0 (default_pg) Rank 4] Process group watchdog thread terminated with exception: CUDA error: an illegal memory access was encountered
CUDA kernel errors might be asynchronously reported at some other API call, so the stacktrace below might be incorrect.
For debugging consider passing CUDA_LAUNCH_BLOCKING=1
Compile with `TORCH_USE_CUDA_DSA` to enable device-side assertions.

Exception raised from c10_cuda_check_implementation at ../c10/cuda/CUDAException.cpp:43 (most recent call first):
frame #0: c10::Error::Error(c10::SourceLocation, std::string) + 0x96 (0x14b159ecbf86 in /home/charlie/anaconda3/envs/gpt-fast/lib/python3.10/site-packages/torch/lib/libc10.so)
frame #1: c10::detail::torchCheckFail(char const*, char const*, unsigned int, std::string const&) + 0x64 (0x14b159e7ad10 in /home/charlie/anaconda3/envs/gpt-fast/lib/python3.10/site-packages/torch/lib/libc10.so)
frame #2: c10::cuda::c10_cuda_check_implementation(int, char const*, char const*, int, bool) + 0x118 (0x14b159fa6f08 in /home/charlie/anaconda3/envs/gpt-fast/lib/python3.10/site-packages/torch/lib/libc10_cuda.so)
frame #3: c10d::ProcessGroupNCCL::WorkNCCL::finishedGPUExecutionInternal() const + 0x56 (0x14b10c5c5406 in /home/charlie/anaconda3/envs/gpt-fast/lib/python3.10/site-packages/torch/lib/libtorch_cuda.so)
frame #4: c10d::ProcessGroupNCCL::WorkNCCL::isCompleted() + 0xa0 (0x14b10c5ca620 in /home/charlie/anaconda3/envs/gpt-fast/lib/python3.10/site-packages/torch/lib/libtorch_cuda.so)
frame #5: c10d::ProcessGroupNCCL::watchdogHandler() + 0x1da (0x14b10c5d12da in /home/charlie/anaconda3/envs/gpt-fast/lib/python3.10/site-packages/torch/lib/libtorch_cuda.so)
frame #6: c10d::ProcessGroupNCCL::ncclCommWatchdog() + 0x10c (0x14b10c5d371c in /home/charlie/anaconda3/envs/gpt-fast/lib/python3.10/site-packages/torch/lib/libtorch_cuda.so)
frame #7: <unknown function> + 0xd3b75 (0x14b15a2f0b75 in /home/charlie/anaconda3/envs/gpt-fast/bin/../lib/libstdc++.so.6)
frame #8: <unknown function> + 0x94ac3 (0x14b15b38aac3 in /lib/x86_64-linux-gnu/libc.so.6)
frame #9: <unknown function> + 0x126850 (0x14b15b41c850 in /lib/x86_64-linux-gnu/libc.so.6)

Exception raised from ncclCommWatchdog at ../torch/csrc/distributed/c10d/ProcessGroupNCCL.cpp:1521 (most recent call first):
frame #0: c10::Error::Error(c10::SourceLocation, std::string) + 0x96 (0x14b159ecbf86 in /home/charlie/anaconda3/envs/gpt-fast/lib/python3.10/site-packages/torch/lib/libc10.so)
frame #1: <unknown function> + 0xe5aa84 (0x14b10c25ca84 in /home/charlie/anaconda3/envs/gpt-fast/lib/python3.10/site-packages/torch/lib/libtorch_cuda.so)
frame #2: <unknown function> + 0xd3b75 (0x14b15a2f0b75 in /home/charlie/anaconda3/envs/gpt-fast/bin/../lib/libstdc++.so.6)
frame #3: <unknown function> + 0x94ac3 (0x14b15b38aac3 in /lib/x86_64-linux-gnu/libc.so.6)
frame #4: <unknown function> + 0x126850 (0x14b15b41c850 in /lib/x86_64-linux-gnu/libc.so.6)

[rank5]:[E920 09:14:24.588822371 ProcessGroupNCCL.cpp:1515] [PG 0 (default_pg) Rank 5] Process group watchdog thread terminated with exception: CUDA error: an illegal memory access was encountered
CUDA kernel errors might be asynchronously reported at some other API call, so the stacktrace below might be incorrect.
For debugging consider passing CUDA_LAUNCH_BLOCKING=1
Compile with `TORCH_USE_CUDA_DSA` to enable device-side assertions.

Exception raised from c10_cuda_check_implementation at ../c10/cuda/CUDAException.cpp:43 (most recent call first):
frame #0: c10::Error::Error(c10::SourceLocation, std::string) + 0x96 (0x148512179f86 in /home/charlie/anaconda3/envs/gpt-fast/lib/python3.10/site-packages/torch/lib/libc10.so)
frame #1: c10::detail::torchCheckFail(char const*, char const*, unsigned int, std::string const&) + 0x64 (0x148512128d10 in /home/charlie/anaconda3/envs/gpt-fast/lib/python3.10/site-packages/torch/lib/libc10.so)
frame #2: c10::cuda::c10_cuda_check_implementation(int, char const*, char const*, int, bool) + 0x118 (0x148560d75f08 in /home/charlie/anaconda3/envs/gpt-fast/lib/python3.10/site-packages/torch/lib/libc10_cuda.so)
frame #3: c10d::ProcessGroupNCCL::WorkNCCL::finishedGPUExecutionInternal() const + 0x56 (0x1485133c5406 in /home/charlie/anaconda3/envs/gpt-fast/lib/python3.10/site-packages/torch/lib/libtorch_cuda.so)
frame #4: c10d::ProcessGroupNCCL::WorkNCCL::isCompleted() + 0xa0 (0x1485133ca620 in /home/charlie/anaconda3/envs/gpt-fast/lib/python3.10/site-packages/torch/lib/libtorch_cuda.so)
frame #5: c10d::ProcessGroupNCCL::watchdogHandler() + 0x1da (0x1485133d12da in /home/charlie/anaconda3/envs/gpt-fast/lib/python3.10/site-packages/torch/lib/libtorch_cuda.so)
frame #6: c10d::ProcessGroupNCCL::ncclCommWatchdog() + 0x10c (0x1485133d371c in /home/charlie/anaconda3/envs/gpt-fast/lib/python3.10/site-packages/torch/lib/libtorch_cuda.so)
frame #7: <unknown function> + 0xd3b75 (0x1485610f0b75 in /home/charlie/anaconda3/envs/gpt-fast/bin/../lib/libstdc++.so.6)
frame #8: <unknown function> + 0x94ac3 (0x14856211aac3 in /lib/x86_64-linux-gnu/libc.so.6)
frame #9: <unknown function> + 0x126850 (0x1485621ac850 in /lib/x86_64-linux-gnu/libc.so.6)

terminate called after throwing an instance of 'c10::DistBackendError'
  what():  [PG 0 (default_pg) Rank 5] Process group watchdog thread terminated with exception: CUDA error: an illegal memory access was encountered
CUDA kernel errors might be asynchronously reported at some other API call, so the stacktrace below might be incorrect.
For debugging consider passing CUDA_LAUNCH_BLOCKING=1
Compile with `TORCH_USE_CUDA_DSA` to enable device-side assertions.

Exception raised from c10_cuda_check_implementation at ../c10/cuda/CUDAException.cpp:43 (most recent call first):
frame #0: c10::Error::Error(c10::SourceLocation, std::string) + 0x96 (0x148512179f86 in /home/charlie/anaconda3/envs/gpt-fast/lib/python3.10/site-packages/torch/lib/libc10.so)
frame #1: c10::detail::torchCheckFail(char const*, char const*, unsigned int, std::string const&) + 0x64 (0x148512128d10 in /home/charlie/anaconda3/envs/gpt-fast/lib/python3.10/site-packages/torch/lib/libc10.so)
frame #2: c10::cuda::c10_cuda_check_implementation(int, char const*, char const*, int, bool) + 0x118 (0x148560d75f08 in /home/charlie/anaconda3/envs/gpt-fast/lib/python3.10/site-packages/torch/lib/libc10_cuda.so)
frame #3: c10d::ProcessGroupNCCL::WorkNCCL::finishedGPUExecutionInternal() const + 0x56 (0x1485133c5406 in /home/charlie/anaconda3/envs/gpt-fast/lib/python3.10/site-packages/torch/lib/libtorch_cuda.so)
frame #4: c10d::ProcessGroupNCCL::WorkNCCL::isCompleted() + 0xa0 (0x1485133ca620 in /home/charlie/anaconda3/envs/gpt-fast/lib/python3.10/site-packages/torch/lib/libtorch_cuda.so)
frame #5: c10d::ProcessGroupNCCL::watchdogHandler() + 0x1da (0x1485133d12da in /home/charlie/anaconda3/envs/gpt-fast/lib/python3.10/site-packages/torch/lib/libtorch_cuda.so)
frame #6: c10d::ProcessGroupNCCL::ncclCommWatchdog() + 0x10c (0x1485133d371c in /home/charlie/anaconda3/envs/gpt-fast/lib/python3.10/site-packages/torch/lib/libtorch_cuda.so)
frame #7: <unknown function> + 0xd3b75 (0x1485610f0b75 in /home/charlie/anaconda3/envs/gpt-fast/bin/../lib/libstdc++.so.6)
frame #8: <unknown function> + 0x94ac3 (0x14856211aac3 in /lib/x86_64-linux-gnu/libc.so.6)
frame #9: <unknown function> + 0x126850 (0x1485621ac850 in /lib/x86_64-linux-gnu/libc.so.6)

Exception raised from ncclCommWatchdog at ../torch/csrc/distributed/c10d/ProcessGroupNCCL.cpp:1521 (most recent call first):
frame #0: c10::Error::Error(c10::SourceLocation, std::string) + 0x96 (0x148512179f86 in /home/charlie/anaconda3/envs/gpt-fast/lib/python3.10/site-packages/torch/lib/libc10.so)
frame #1: <unknown function> + 0xe5aa84 (0x14851305ca84 in /home/charlie/anaconda3/envs/gpt-fast/lib/python3.10/site-packages/torch/lib/libtorch_cuda.so)
frame #2: <unknown function> + 0xd3b75 (0x1485610f0b75 in /home/charlie/anaconda3/envs/gpt-fast/bin/../lib/libstdc++.so.6)
frame #3: <unknown function> + 0x94ac3 (0x14856211aac3 in /lib/x86_64-linux-gnu/libc.so.6)
frame #4: <unknown function> + 0x126850 (0x1485621ac850 in /lib/x86_64-linux-gnu/libc.so.6)

[rank1]:[E920 09:14:24.632799390 ProcessGroupNCCL.cpp:1515] [PG 0 (default_pg) Rank 1] Process group watchdog thread terminated with exception: CUDA error: an illegal memory access was encountered
CUDA kernel errors might be asynchronously reported at some other API call, so the stacktrace below might be incorrect.
For debugging consider passing CUDA_LAUNCH_BLOCKING=1
Compile with `TORCH_USE_CUDA_DSA` to enable device-side assertions.

Exception raised from c10_cuda_check_implementation at ../c10/cuda/CUDAException.cpp:43 (most recent call first):
frame #0: c10::Error::Error(c10::SourceLocation, std::string) + 0x96 (0x14bb6b377f86 in /home/charlie/anaconda3/envs/gpt-fast/lib/python3.10/site-packages/torch/lib/libc10.so)
frame #1: c10::detail::torchCheckFail(char const*, char const*, unsigned int, std::string const&) + 0x64 (0x14bb6b326d10 in /home/charlie/anaconda3/envs/gpt-fast/lib/python3.10/site-packages/torch/lib/libc10.so)
frame #2: c10::cuda::c10_cuda_check_implementation(int, char const*, char const*, int, bool) + 0x118 (0x14bb6bafef08 in /home/charlie/anaconda3/envs/gpt-fast/lib/python3.10/site-packages/torch/lib/libc10_cuda.so)
frame #3: c10d::ProcessGroupNCCL::WorkNCCL::finishedGPUExecutionInternal() const + 0x56 (0x14bb1d9c5406 in /home/charlie/anaconda3/envs/gpt-fast/lib/python3.10/site-packages/torch/lib/libtorch_cuda.so)
frame #4: c10d::ProcessGroupNCCL::WorkNCCL::isCompleted() + 0xa0 (0x14bb1d9ca620 in /home/charlie/anaconda3/envs/gpt-fast/lib/python3.10/site-packages/torch/lib/libtorch_cuda.so)
frame #5: c10d::ProcessGroupNCCL::watchdogHandler() + 0x1da (0x14bb1d9d12da in /home/charlie/anaconda3/envs/gpt-fast/lib/python3.10/site-packages/torch/lib/libtorch_cuda.so)
frame #6: c10d::ProcessGroupNCCL::ncclCommWatchdog() + 0x10c (0x14bb1d9d371c in /home/charlie/anaconda3/envs/gpt-fast/lib/python3.10/site-packages/torch/lib/libtorch_cuda.so)
frame #7: <unknown function> + 0xd3b75 (0x14bb6b6f0b75 in /home/charlie/anaconda3/envs/gpt-fast/bin/../lib/libstdc++.so.6)
frame #8: <unknown function> + 0x94ac3 (0x14bb6c7f1ac3 in /lib/x86_64-linux-gnu/libc.so.6)
frame #9: <unknown function> + 0x126850 (0x14bb6c883850 in /lib/x86_64-linux-gnu/libc.so.6)

terminate called after throwing an instance of 'c10::DistBackendError'
  what():  [PG 0 (default_pg) Rank 1] Process group watchdog thread terminated with exception: CUDA error: an illegal memory access was encountered
CUDA kernel errors might be asynchronously reported at some other API call, so the stacktrace below might be incorrect.
For debugging consider passing CUDA_LAUNCH_BLOCKING=1
Compile with `TORCH_USE_CUDA_DSA` to enable device-side assertions.

Exception raised from c10_cuda_check_implementation at ../c10/cuda/CUDAException.cpp:43 (most recent call first):
frame #0: c10::Error::Error(c10::SourceLocation, std::string) + 0x96 (0x14bb6b377f86 in /home/charlie/anaconda3/envs/gpt-fast/lib/python3.10/site-packages/torch/lib/libc10.so)
frame #1: c10::detail::torchCheckFail(char const*, char const*, unsigned int, std::string const&) + 0x64 (0x14bb6b326d10 in /home/charlie/anaconda3/envs/gpt-fast/lib/python3.10/site-packages/torch/lib/libc10.so)
frame #2: c10::cuda::c10_cuda_check_implementation(int, char const*, char const*, int, bool) + 0x118 (0x14bb6bafef08 in /home/charlie/anaconda3/envs/gpt-fast/lib/python3.10/site-packages/torch/lib/libc10_cuda.so)
frame #3: c10d::ProcessGroupNCCL::WorkNCCL::finishedGPUExecutionInternal() const + 0x56 (0x14bb1d9c5406 in /home/charlie/anaconda3/envs/gpt-fast/lib/python3.10/site-packages/torch/lib/libtorch_cuda.so)
frame #4: c10d::ProcessGroupNCCL::WorkNCCL::isCompleted() + 0xa0 (0x14bb1d9ca620 in /home/charlie/anaconda3/envs/gpt-fast/lib/python3.10/site-packages/torch/lib/libtorch_cuda.so)
frame #5: c10d::ProcessGroupNCCL::watchdogHandler() + 0x1da (0x14bb1d9d12da in /home/charlie/anaconda3/envs/gpt-fast/lib/python3.10/site-packages/torch/lib/libtorch_cuda.so)
frame #6: c10d::ProcessGroupNCCL::ncclCommWatchdog() + 0x10c (0x14bb1d9d371c in /home/charlie/anaconda3/envs/gpt-fast/lib/python3.10/site-packages/torch/lib/libtorch_cuda.so)
frame #7: <unknown function> + 0xd3b75 (0x14bb6b6f0b75 in /home/charlie/anaconda3/envs/gpt-fast/bin/../lib/libstdc++.so.6)
frame #8: <unknown function> + 0x94ac3 (0x14bb6c7f1ac3 in /lib/x86_64-linux-gnu/libc.so.6)
frame #9: <unknown function> + 0x126850 (0x14bb6c883850 in /lib/x86_64-linux-gnu/libc.so.6)

Exception raised from ncclCommWatchdog at ../torch/csrc/distributed/c10d/ProcessGroupNCCL.cpp:1521 (most recent call first):
frame #0: c10::Error::Error(c10::SourceLocation, std::string) + 0x96 (0x14bb6b377f86 in /home/charlie/anaconda3/envs/gpt-fast/lib/python3.10/site-packages/torch/lib/libc10.so)
frame #1: <unknown function> + 0xe5aa84 (0x14bb1d65ca84 in /home/charlie/anaconda3/envs/gpt-fast/lib/python3.10/site-packages/torch/lib/libtorch_cuda.so)
frame #2: <unknown function> + 0xd3b75 (0x14bb6b6f0b75 in /home/charlie/anaconda3/envs/gpt-fast/bin/../lib/libstdc++.so.6)
frame #3: <unknown function> + 0x94ac3 (0x14bb6c7f1ac3 in /lib/x86_64-linux-gnu/libc.so.6)
frame #4: <unknown function> + 0x126850 (0x14bb6c883850 in /lib/x86_64-linux-gnu/libc.so.6)

[rank3]:[E920 09:14:24.678230333 ProcessGroupNCCL.cpp:1515] [PG 0 (default_pg) Rank 3] Process group watchdog thread terminated with exception: CUDA error: an illegal memory access was encountered
CUDA kernel errors might be asynchronously reported at some other API call, so the stacktrace below might be incorrect.
For debugging consider passing CUDA_LAUNCH_BLOCKING=1
Compile with `TORCH_USE_CUDA_DSA` to enable device-side assertions.

Exception raised from c10_cuda_check_implementation at ../c10/cuda/CUDAException.cpp:43 (most recent call first):
frame #0: c10::Error::Error(c10::SourceLocation, std::string) + 0x96 (0x1476f6977f86 in /home/charlie/anaconda3/envs/gpt-fast/lib/python3.10/site-packages/torch/lib/libc10.so)
frame #1: c10::detail::torchCheckFail(char const*, char const*, unsigned int, std::string const&) + 0x64 (0x1476f6926d10 in /home/charlie/anaconda3/envs/gpt-fast/lib/python3.10/site-packages/torch/lib/libc10.so)
frame #2: c10::cuda::c10_cuda_check_implementation(int, char const*, char const*, int, bool) + 0x118 (0x1476f7171f08 in /home/charlie/anaconda3/envs/gpt-fast/lib/python3.10/site-packages/torch/lib/libc10_cuda.so)
frame #3: c10d::ProcessGroupNCCL::WorkNCCL::finishedGPUExecutionInternal() const + 0x56 (0x1476a8fc5406 in /home/charlie/anaconda3/envs/gpt-fast/lib/python3.10/site-packages/torch/lib/libtorch_cuda.so)
frame #4: c10d::ProcessGroupNCCL::WorkNCCL::isCompleted() + 0xa0 (0x1476a8fca620 in /home/charlie/anaconda3/envs/gpt-fast/lib/python3.10/site-packages/torch/lib/libtorch_cuda.so)
frame #5: c10d::ProcessGroupNCCL::watchdogHandler() + 0x1da (0x1476a8fd12da in /home/charlie/anaconda3/envs/gpt-fast/lib/python3.10/site-packages/torch/lib/libtorch_cuda.so)
frame #6: c10d::ProcessGroupNCCL::ncclCommWatchdog() + 0x10c (0x1476a8fd371c in /home/charlie/anaconda3/envs/gpt-fast/lib/python3.10/site-packages/torch/lib/libtorch_cuda.so)
frame #7: <unknown function> + 0xd3b75 (0x1476f6cf0b75 in /home/charlie/anaconda3/envs/gpt-fast/bin/../lib/libstdc++.so.6)
frame #8: <unknown function> + 0x94ac3 (0x1476f7e64ac3 in /lib/x86_64-linux-gnu/libc.so.6)
frame #9: <unknown function> + 0x126850 (0x1476f7ef6850 in /lib/x86_64-linux-gnu/libc.so.6)

terminate called after throwing an instance of 'c10::DistBackendError'
  what():  [PG 0 (default_pg) Rank 3] Process group watchdog thread terminated with exception: CUDA error: an illegal memory access was encountered
CUDA kernel errors might be asynchronously reported at some other API call, so the stacktrace below might be incorrect.
For debugging consider passing CUDA_LAUNCH_BLOCKING=1
Compile with `TORCH_USE_CUDA_DSA` to enable device-side assertions.

Exception raised from c10_cuda_check_implementation at ../c10/cuda/CUDAException.cpp:43 (most recent call first):
frame #0: c10::Error::Error(c10::SourceLocation, std::string) + 0x96 (0x1476f6977f86 in /home/charlie/anaconda3/envs/gpt-fast/lib/python3.10/site-packages/torch/lib/libc10.so)
frame #1: c10::detail::torchCheckFail(char const*, char const*, unsigned int, std::string const&) + 0x64 (0x1476f6926d10 in /home/charlie/anaconda3/envs/gpt-fast/lib/python3.10/site-packages/torch/lib/libc10.so)
frame #2: c10::cuda::c10_cuda_check_implementation(int, char const*, char const*, int, bool) + 0x118 (0x1476f7171f08 in /home/charlie/anaconda3/envs/gpt-fast/lib/python3.10/site-packages/torch/lib/libc10_cuda.so)
frame #3: c10d::ProcessGroupNCCL::WorkNCCL::finishedGPUExecutionInternal() const + 0x56 (0x1476a8fc5406 in /home/charlie/anaconda3/envs/gpt-fast/lib/python3.10/site-packages/torch/lib/libtorch_cuda.so)
frame #4: c10d::ProcessGroupNCCL::WorkNCCL::isCompleted() + 0xa0 (0x1476a8fca620 in /home/charlie/anaconda3/envs/gpt-fast/lib/python3.10/site-packages/torch/lib/libtorch_cuda.so)
frame #5: c10d::ProcessGroupNCCL::watchdogHandler() + 0x1da (0x1476a8fd12da in /home/charlie/anaconda3/envs/gpt-fast/lib/python3.10/site-packages/torch/lib/libtorch_cuda.so)
frame #6: c10d::ProcessGroupNCCL::ncclCommWatchdog() + 0x10c (0x1476a8fd371c in /home/charlie/anaconda3/envs/gpt-fast/lib/python3.10/site-packages/torch/lib/libtorch_cuda.so)
frame #7: <unknown function> + 0xd3b75 (0x1476f6cf0b75 in /home/charlie/anaconda3/envs/gpt-fast/bin/../lib/libstdc++.so.6)
frame #8: <unknown function> + 0x94ac3 (0x1476f7e64ac3 in /lib/x86_64-linux-gnu/libc.so.6)
frame #9: <unknown function> + 0x126850 (0x1476f7ef6850 in /lib/x86_64-linux-gnu/libc.so.6)

Exception raised from ncclCommWatchdog at ../torch/csrc/distributed/c10d/ProcessGroupNCCL.cpp:1521 (most recent call first):
frame #0: c10::Error::Error(c10::SourceLocation, std::string) + 0x96 (0x1476f6977f86 in /home/charlie/anaconda3/envs/gpt-fast/lib/python3.10/site-packages/torch/lib/libc10.so)
frame #1: <unknown function> + 0xe5aa84 (0x1476a8c5ca84 in /home/charlie/anaconda3/envs/gpt-fast/lib/python3.10/site-packages/torch/lib/libtorch_cuda.so)
frame #2: <unknown function> + 0xd3b75 (0x1476f6cf0b75 in /home/charlie/anaconda3/envs/gpt-fast/bin/../lib/libstdc++.so.6)
frame #3: <unknown function> + 0x94ac3 (0x1476f7e64ac3 in /lib/x86_64-linux-gnu/libc.so.6)
frame #4: <unknown function> + 0x126850 (0x1476f7ef6850 in /lib/x86_64-linux-gnu/libc.so.6)

[rank0]:[E920 09:14:24.722430365 ProcessGroupNCCL.cpp:1515] [PG 0 (default_pg) Rank 0] Process group watchdog thread terminated with exception: CUDA error: an illegal memory access was encountered
CUDA kernel errors might be asynchronously reported at some other API call, so the stacktrace below might be incorrect.
For debugging consider passing CUDA_LAUNCH_BLOCKING=1
Compile with `TORCH_USE_CUDA_DSA` to enable device-side assertions.

Exception raised from c10_cuda_check_implementation at ../c10/cuda/CUDAException.cpp:43 (most recent call first):
frame #0: c10::Error::Error(c10::SourceLocation, std::string) + 0x96 (0x14fff5977f86 in /home/charlie/anaconda3/envs/gpt-fast/lib/python3.10/site-packages/torch/lib/libc10.so)
frame #1: c10::detail::torchCheckFail(char const*, char const*, unsigned int, std::string const&) + 0x64 (0x14fff5926d10 in /home/charlie/anaconda3/envs/gpt-fast/lib/python3.10/site-packages/torch/lib/libc10.so)
frame #2: c10::cuda::c10_cuda_check_implementation(int, char const*, char const*, int, bool) + 0x118 (0x14fff6110f08 in /home/charlie/anaconda3/envs/gpt-fast/lib/python3.10/site-packages/torch/lib/libc10_cuda.so)
frame #3: c10d::ProcessGroupNCCL::WorkNCCL::finishedGPUExecutionInternal() const + 0x56 (0x14ffa7fc5406 in /home/charlie/anaconda3/envs/gpt-fast/lib/python3.10/site-packages/torch/lib/libtorch_cuda.so)
frame #4: c10d::ProcessGroupNCCL::WorkNCCL::isCompleted() + 0xa0 (0x14ffa7fca620 in /home/charlie/anaconda3/envs/gpt-fast/lib/python3.10/site-packages/torch/lib/libtorch_cuda.so)
frame #5: c10d::ProcessGroupNCCL::watchdogHandler() + 0x1da (0x14ffa7fd12da in /home/charlie/anaconda3/envs/gpt-fast/lib/python3.10/site-packages/torch/lib/libtorch_cuda.so)
frame #6: c10d::ProcessGroupNCCL::ncclCommWatchdog() + 0x10c (0x14ffa7fd371c in /home/charlie/anaconda3/envs/gpt-fast/lib/python3.10/site-packages/torch/lib/libtorch_cuda.so)
frame #7: <unknown function> + 0xd3b75 (0x14fff5cf0b75 in /home/charlie/anaconda3/envs/gpt-fast/bin/../lib/libstdc++.so.6)
frame #8: <unknown function> + 0x94ac3 (0x14fff6e03ac3 in /lib/x86_64-linux-gnu/libc.so.6)
frame #9: <unknown function> + 0x126850 (0x14fff6e95850 in /lib/x86_64-linux-gnu/libc.so.6)

terminate called after throwing an instance of 'c10::DistBackendError'
  what():  [PG 0 (default_pg) Rank 0] Process group watchdog thread terminated with exception: CUDA error: an illegal memory access was encountered
CUDA kernel errors might be asynchronously reported at some other API call, so the stacktrace below might be incorrect.
For debugging consider passing CUDA_LAUNCH_BLOCKING=1
Compile with `TORCH_USE_CUDA_DSA` to enable device-side assertions.

Exception raised from c10_cuda_check_implementation at ../c10/cuda/CUDAException.cpp:43 (most recent call first):
frame #0: c10::Error::Error(c10::SourceLocation, std::string) + 0x96 (0x14fff5977f86 in /home/charlie/anaconda3/envs/gpt-fast/lib/python3.10/site-packages/torch/lib/libc10.so)
frame #1: c10::detail::torchCheckFail(char const*, char const*, unsigned int, std::string const&) + 0x64 (0x14fff5926d10 in /home/charlie/anaconda3/envs/gpt-fast/lib/python3.10/site-packages/torch/lib/libc10.so)
frame #2: c10::cuda::c10_cuda_check_implementation(int, char const*, char const*, int, bool) + 0x118 (0x14fff6110f08 in /home/charlie/anaconda3/envs/gpt-fast/lib/python3.10/site-packages/torch/lib/libc10_cuda.so)
frame #3: c10d::ProcessGroupNCCL::WorkNCCL::finishedGPUExecutionInternal() const + 0x56 (0x14ffa7fc5406 in /home/charlie/anaconda3/envs/gpt-fast/lib/python3.10/site-packages/torch/lib/libtorch_cuda.so)
frame #4: c10d::ProcessGroupNCCL::WorkNCCL::isCompleted() + 0xa0 (0x14ffa7fca620 in /home/charlie/anaconda3/envs/gpt-fast/lib/python3.10/site-packages/torch/lib/libtorch_cuda.so)
frame #5: c10d::ProcessGroupNCCL::watchdogHandler() + 0x1da (0x14ffa7fd12da in /home/charlie/anaconda3/envs/gpt-fast/lib/python3.10/site-packages/torch/lib/libtorch_cuda.so)
frame #6: c10d::ProcessGroupNCCL::ncclCommWatchdog() + 0x10c (0x14ffa7fd371c in /home/charlie/anaconda3/envs/gpt-fast/lib/python3.10/site-packages/torch/lib/libtorch_cuda.so)
frame #7: <unknown function> + 0xd3b75 (0x14fff5cf0b75 in /home/charlie/anaconda3/envs/gpt-fast/bin/../lib/libstdc++.so.6)
frame #8: <unknown function> + 0x94ac3 (0x14fff6e03ac3 in /lib/x86_64-linux-gnu/libc.so.6)
frame #9: <unknown function> + 0x126850 (0x14fff6e95850 in /lib/x86_64-linux-gnu/libc.so.6)

Exception raised from ncclCommWatchdog at ../torch/csrc/distributed/c10d/ProcessGroupNCCL.cpp:1521 (most recent call first):
frame #0: c10::Error::Error(c10::SourceLocation, std::string) + 0x96 (0x14fff5977f86 in /home/charlie/anaconda3/envs/gpt-fast/lib/python3.10/site-packages/torch/lib/libc10.so)
frame #1: <unknown function> + 0xe5aa84 (0x14ffa7c5ca84 in /home/charlie/anaconda3/envs/gpt-fast/lib/python3.10/site-packages/torch/lib/libtorch_cuda.so)
frame #2: <unknown function> + 0xd3b75 (0x14fff5cf0b75 in /home/charlie/anaconda3/envs/gpt-fast/bin/../lib/libstdc++.so.6)
frame #3: <unknown function> + 0x94ac3 (0x14fff6e03ac3 in /lib/x86_64-linux-gnu/libc.so.6)
frame #4: <unknown function> + 0x126850 (0x14fff6e95850 in /lib/x86_64-linux-gnu/libc.so.6)

[rank2]:[E920 09:14:24.723276193 ProcessGroupNCCL.cpp:1515] [PG 0 (default_pg) Rank 2] Process group watchdog thread terminated with exception: CUDA error: an illegal memory access was encountered
CUDA kernel errors might be asynchronously reported at some other API call, so the stacktrace below might be incorrect.
For debugging consider passing CUDA_LAUNCH_BLOCKING=1
Compile with `TORCH_USE_CUDA_DSA` to enable device-side assertions.

Exception raised from c10_cuda_check_implementation at ../c10/cuda/CUDAException.cpp:43 (most recent call first):
frame #0: c10::Error::Error(c10::SourceLocation, std::string) + 0x96 (0x1534418cbf86 in /home/charlie/anaconda3/envs/gpt-fast/lib/python3.10/site-packages/torch/lib/libc10.so)
frame #1: c10::detail::torchCheckFail(char const*, char const*, unsigned int, std::string const&) + 0x64 (0x15344187ad10 in /home/charlie/anaconda3/envs/gpt-fast/lib/python3.10/site-packages/torch/lib/libc10.so)
frame #2: c10::cuda::c10_cuda_check_implementation(int, char const*, char const*, int, bool) + 0x118 (0x1534419a6f08 in /home/charlie/anaconda3/envs/gpt-fast/lib/python3.10/site-packages/torch/lib/libc10_cuda.so)
frame #3: c10d::ProcessGroupNCCL::WorkNCCL::finishedGPUExecutionInternal() const + 0x56 (0x1533f3fc5406 in /home/charlie/anaconda3/envs/gpt-fast/lib/python3.10/site-packages/torch/lib/libtorch_cuda.so)
frame #4: c10d::ProcessGroupNCCL::WorkNCCL::isCompleted() + 0xa0 (0x1533f3fca620 in /home/charlie/anaconda3/envs/gpt-fast/lib/python3.10/site-packages/torch/lib/libtorch_cuda.so)
frame #5: c10d::ProcessGroupNCCL::watchdogHandler() + 0x1da (0x1533f3fd12da in /home/charlie/anaconda3/envs/gpt-fast/lib/python3.10/site-packages/torch/lib/libtorch_cuda.so)
frame #6: c10d::ProcessGroupNCCL::ncclCommWatchdog() + 0x10c (0x1533f3fd371c in /home/charlie/anaconda3/envs/gpt-fast/lib/python3.10/site-packages/torch/lib/libtorch_cuda.so)
frame #7: <unknown function> + 0xd3b75 (0x153441cf0b75 in /home/charlie/anaconda3/envs/gpt-fast/bin/../lib/libstdc++.so.6)
frame #8: <unknown function> + 0x94ac3 (0x153442d8fac3 in /lib/x86_64-linux-gnu/libc.so.6)
frame #9: <unknown function> + 0x126850 (0x153442e21850 in /lib/x86_64-linux-gnu/libc.so.6)

terminate called after throwing an instance of 'c10::DistBackendError'
  what():  [PG 0 (default_pg) Rank 2] Process group watchdog thread terminated with exception: CUDA error: an illegal memory access was encountered
CUDA kernel errors might be asynchronously reported at some other API call, so the stacktrace below might be incorrect.
For debugging consider passing CUDA_LAUNCH_BLOCKING=1
Compile with `TORCH_USE_CUDA_DSA` to enable device-side assertions.

Exception raised from c10_cuda_check_implementation at ../c10/cuda/CUDAException.cpp:43 (most recent call first):
frame #0: c10::Error::Error(c10::SourceLocation, std::string) + 0x96 (0x1534418cbf86 in /home/charlie/anaconda3/envs/gpt-fast/lib/python3.10/site-packages/torch/lib/libc10.so)
frame #1: c10::detail::torchCheckFail(char const*, char const*, unsigned int, std::string const&) + 0x64 (0x15344187ad10 in /home/charlie/anaconda3/envs/gpt-fast/lib/python3.10/site-packages/torch/lib/libc10.so)
frame #2: c10::cuda::c10_cuda_check_implementation(int, char const*, char const*, int, bool) + 0x118 (0x1534419a6f08 in /home/charlie/anaconda3/envs/gpt-fast/lib/python3.10/site-packages/torch/lib/libc10_cuda.so)
frame #3: c10d::ProcessGroupNCCL::WorkNCCL::finishedGPUExecutionInternal() const + 0x56 (0x1533f3fc5406 in /home/charlie/anaconda3/envs/gpt-fast/lib/python3.10/site-packages/torch/lib/libtorch_cuda.so)
frame #4: c10d::ProcessGroupNCCL::WorkNCCL::isCompleted() + 0xa0 (0x1533f3fca620 in /home/charlie/anaconda3/envs/gpt-fast/lib/python3.10/site-packages/torch/lib/libtorch_cuda.so)
frame #5: c10d::ProcessGroupNCCL::watchdogHandler() + 0x1da (0x1533f3fd12da in /home/charlie/anaconda3/envs/gpt-fast/lib/python3.10/site-packages/torch/lib/libtorch_cuda.so)
frame #6: c10d::ProcessGroupNCCL::ncclCommWatchdog() + 0x10c (0x1533f3fd371c in /home/charlie/anaconda3/envs/gpt-fast/lib/python3.10/site-packages/torch/lib/libtorch_cuda.so)
frame #7: <unknown function> + 0xd3b75 (0x153441cf0b75 in /home/charlie/anaconda3/envs/gpt-fast/bin/../lib/libstdc++.so.6)
frame #8: <unknown function> + 0x94ac3 (0x153442d8fac3 in /lib/x86_64-linux-gnu/libc.so.6)
frame #9: <unknown function> + 0x126850 (0x153442e21850 in /lib/x86_64-linux-gnu/libc.so.6)

Exception raised from ncclCommWatchdog at ../torch/csrc/distributed/c10d/ProcessGroupNCCL.cpp:1521 (most recent call first):
frame #0: c10::Error::Error(c10::SourceLocation, std::string) + 0x96 (0x1534418cbf86 in /home/charlie/anaconda3/envs/gpt-fast/lib/python3.10/site-packages/torch/lib/libc10.so)
frame #1: <unknown function> + 0xe5aa84 (0x1533f3c5ca84 in /home/charlie/anaconda3/envs/gpt-fast/lib/python3.10/site-packages/torch/lib/libtorch_cuda.so)
frame #2: <unknown function> + 0xd3b75 (0x153441cf0b75 in /home/charlie/anaconda3/envs/gpt-fast/bin/../lib/libstdc++.so.6)
frame #3: <unknown function> + 0x94ac3 (0x153442d8fac3 in /lib/x86_64-linux-gnu/libc.so.6)
frame #4: <unknown function> + 0x126850 (0x153442e21850 in /lib/x86_64-linux-gnu/libc.so.6)

[rank6]:[E920 09:14:24.768582279 ProcessGroupNCCL.cpp:1515] [PG 0 (default_pg) Rank 6] Process group watchdog thread terminated with exception: CUDA error: an illegal memory access was encountered
CUDA kernel errors might be asynchronously reported at some other API call, so the stacktrace below might be incorrect.
For debugging consider passing CUDA_LAUNCH_BLOCKING=1
Compile with `TORCH_USE_CUDA_DSA` to enable device-side assertions.

Exception raised from c10_cuda_check_implementation at ../c10/cuda/CUDAException.cpp:43 (most recent call first):
frame #0: c10::Error::Error(c10::SourceLocation, std::string) + 0x96 (0x147f498cbf86 in /home/charlie/anaconda3/envs/gpt-fast/lib/python3.10/site-packages/torch/lib/libc10.so)
frame #1: c10::detail::torchCheckFail(char const*, char const*, unsigned int, std::string const&) + 0x64 (0x147f4987ad10 in /home/charlie/anaconda3/envs/gpt-fast/lib/python3.10/site-packages/torch/lib/libc10.so)
frame #2: c10::cuda::c10_cuda_check_implementation(int, char const*, char const*, int, bool) + 0x118 (0x147f499a6f08 in /home/charlie/anaconda3/envs/gpt-fast/lib/python3.10/site-packages/torch/lib/libc10_cuda.so)
frame #3: c10d::ProcessGroupNCCL::WorkNCCL::finishedGPUExecutionInternal() const + 0x56 (0x147efbfc5406 in /home/charlie/anaconda3/envs/gpt-fast/lib/python3.10/site-packages/torch/lib/libtorch_cuda.so)
frame #4: c10d::ProcessGroupNCCL::WorkNCCL::isCompleted() + 0xa0 (0x147efbfca620 in /home/charlie/anaconda3/envs/gpt-fast/lib/python3.10/site-packages/torch/lib/libtorch_cuda.so)
frame #5: c10d::ProcessGroupNCCL::watchdogHandler() + 0x1da (0x147efbfd12da in /home/charlie/anaconda3/envs/gpt-fast/lib/python3.10/site-packages/torch/lib/libtorch_cuda.so)
frame #6: c10d::ProcessGroupNCCL::ncclCommWatchdog() + 0x10c (0x147efbfd371c in /home/charlie/anaconda3/envs/gpt-fast/lib/python3.10/site-packages/torch/lib/libtorch_cuda.so)
frame #7: <unknown function> + 0xd3b75 (0x147f49cf0b75 in /home/charlie/anaconda3/envs/gpt-fast/bin/../lib/libstdc++.so.6)
frame #8: <unknown function> + 0x94ac3 (0x147f4ad5fac3 in /lib/x86_64-linux-gnu/libc.so.6)
frame #9: <unknown function> + 0x126850 (0x147f4adf1850 in /lib/x86_64-linux-gnu/libc.so.6)

terminate called after throwing an instance of 'c10::DistBackendError'
  what():  [PG 0 (default_pg) Rank 6] Process group watchdog thread terminated with exception: CUDA error: an illegal memory access was encountered
CUDA kernel errors might be asynchronously reported at some other API call, so the stacktrace below might be incorrect.
For debugging consider passing CUDA_LAUNCH_BLOCKING=1
Compile with `TORCH_USE_CUDA_DSA` to enable device-side assertions.

Exception raised from c10_cuda_check_implementation at ../c10/cuda/CUDAException.cpp:43 (most recent call first):
frame #0: c10::Error::Error(c10::SourceLocation, std::string) + 0x96 (0x147f498cbf86 in /home/charlie/anaconda3/envs/gpt-fast/lib/python3.10/site-packages/torch/lib/libc10.so)
frame #1: c10::detail::torchCheckFail(char const*, char const*, unsigned int, std::string const&) + 0x64 (0x147f4987ad10 in /home/charlie/anaconda3/envs/gpt-fast/lib/python3.10/site-packages/torch/lib/libc10.so)
frame #2: c10::cuda::c10_cuda_check_implementation(int, char const*, char const*, int, bool) + 0x118 (0x147f499a6f08 in /home/charlie/anaconda3/envs/gpt-fast/lib/python3.10/site-packages/torch/lib/libc10_cuda.so)
frame #3: c10d::ProcessGroupNCCL::WorkNCCL::finishedGPUExecutionInternal() const + 0x56 (0x147efbfc5406 in /home/charlie/anaconda3/envs/gpt-fast/lib/python3.10/site-packages/torch/lib/libtorch_cuda.so)
frame #4: c10d::ProcessGroupNCCL::WorkNCCL::isCompleted() + 0xa0 (0x147efbfca620 in /home/charlie/anaconda3/envs/gpt-fast/lib/python3.10/site-packages/torch/lib/libtorch_cuda.so)
frame #5: c10d::ProcessGroupNCCL::watchdogHandler() + 0x1da (0x147efbfd12da in /home/charlie/anaconda3/envs/gpt-fast/lib/python3.10/site-packages/torch/lib/libtorch_cuda.so)
frame #6: c10d::ProcessGroupNCCL::ncclCommWatchdog() + 0x10c (0x147efbfd371c in /home/charlie/anaconda3/envs/gpt-fast/lib/python3.10/site-packages/torch/lib/libtorch_cuda.so)
frame #7: <unknown function> + 0xd3b75 (0x147f49cf0b75 in /home/charlie/anaconda3/envs/gpt-fast/bin/../lib/libstdc++.so.6)
frame #8: <unknown function> + 0x94ac3 (0x147f4ad5fac3 in /lib/x86_64-linux-gnu/libc.so.6)
frame #9: <unknown function> + 0x126850 (0x147f4adf1850 in /lib/x86_64-linux-gnu/libc.so.6)

Exception raised from ncclCommWatchdog at ../torch/csrc/distributed/c10d/ProcessGroupNCCL.cpp:1521 (most recent call first):
frame #0: c10::Error::Error(c10::SourceLocation, std::string) + 0x96 (0x147f498cbf86 in /home/charlie/anaconda3/envs/gpt-fast/lib/python3.10/site-packages/torch/lib/libc10.so)
frame #1: <unknown function> + 0xe5aa84 (0x147efbc5ca84 in /home/charlie/anaconda3/envs/gpt-fast/lib/python3.10/site-packages/torch/lib/libtorch_cuda.so)
frame #2: <unknown function> + 0xd3b75 (0x147f49cf0b75 in /home/charlie/anaconda3/envs/gpt-fast/bin/../lib/libstdc++.so.6)
frame #3: <unknown function> + 0x94ac3 (0x147f4ad5fac3 in /lib/x86_64-linux-gnu/libc.so.6)
frame #4: <unknown function> + 0x126850 (0x147f4adf1850 in /lib/x86_64-linux-gnu/libc.so.6)

[rank7]:[E920 09:14:24.775881208 ProcessGroupNCCL.cpp:1515] [PG 0 (default_pg) Rank 7] Process group watchdog thread terminated with exception: CUDA error: an illegal memory access was encountered
CUDA kernel errors might be asynchronously reported at some other API call, so the stacktrace below might be incorrect.
For debugging consider passing CUDA_LAUNCH_BLOCKING=1
Compile with `TORCH_USE_CUDA_DSA` to enable device-side assertions.

Exception raised from c10_cuda_check_implementation at ../c10/cuda/CUDAException.cpp:43 (most recent call first):
frame #0: c10::Error::Error(c10::SourceLocation, std::string) + 0x96 (0x149b2a0cbf86 in /home/charlie/anaconda3/envs/gpt-fast/lib/python3.10/site-packages/torch/lib/libc10.so)
frame #1: c10::detail::torchCheckFail(char const*, char const*, unsigned int, std::string const&) + 0x64 (0x149b2a07ad10 in /home/charlie/anaconda3/envs/gpt-fast/lib/python3.10/site-packages/torch/lib/libc10.so)
frame #2: c10::cuda::c10_cuda_check_implementation(int, char const*, char const*, int, bool) + 0x118 (0x149b2a1a6f08 in /home/charlie/anaconda3/envs/gpt-fast/lib/python3.10/site-packages/torch/lib/libc10_cuda.so)
frame #3: c10d::ProcessGroupNCCL::WorkNCCL::finishedGPUExecutionInternal() const + 0x56 (0x149adc7c5406 in /home/charlie/anaconda3/envs/gpt-fast/lib/python3.10/site-packages/torch/lib/libtorch_cuda.so)
frame #4: c10d::ProcessGroupNCCL::WorkNCCL::isCompleted() + 0xa0 (0x149adc7ca620 in /home/charlie/anaconda3/envs/gpt-fast/lib/python3.10/site-packages/torch/lib/libtorch_cuda.so)
frame #5: c10d::ProcessGroupNCCL::watchdogHandler() + 0x1da (0x149adc7d12da in /home/charlie/anaconda3/envs/gpt-fast/lib/python3.10/site-packages/torch/lib/libtorch_cuda.so)
frame #6: c10d::ProcessGroupNCCL::ncclCommWatchdog() + 0x10c (0x149adc7d371c in /home/charlie/anaconda3/envs/gpt-fast/lib/python3.10/site-packages/torch/lib/libtorch_cuda.so)
frame #7: <unknown function> + 0xd3b75 (0x149b2a4f0b75 in /home/charlie/anaconda3/envs/gpt-fast/bin/../lib/libstdc++.so.6)
frame #8: <unknown function> + 0x94ac3 (0x149b2b56bac3 in /lib/x86_64-linux-gnu/libc.so.6)
frame #9: <unknown function> + 0x126850 (0x149b2b5fd850 in /lib/x86_64-linux-gnu/libc.so.6)

terminate called after throwing an instance of 'c10::DistBackendError'
  what():  [PG 0 (default_pg) Rank 7] Process group watchdog thread terminated with exception: CUDA error: an illegal memory access was encountered
CUDA kernel errors might be asynchronously reported at some other API call, so the stacktrace below might be incorrect.
For debugging consider passing CUDA_LAUNCH_BLOCKING=1
Compile with `TORCH_USE_CUDA_DSA` to enable device-side assertions.

Exception raised from c10_cuda_check_implementation at ../c10/cuda/CUDAException.cpp:43 (most recent call first):
frame #0: c10::Error::Error(c10::SourceLocation, std::string) + 0x96 (0x149b2a0cbf86 in /home/charlie/anaconda3/envs/gpt-fast/lib/python3.10/site-packages/torch/lib/libc10.so)
frame #1: c10::detail::torchCheckFail(char const*, char const*, unsigned int, std::string const&) + 0x64 (0x149b2a07ad10 in /home/charlie/anaconda3/envs/gpt-fast/lib/python3.10/site-packages/torch/lib/libc10.so)
frame #2: c10::cuda::c10_cuda_check_implementation(int, char const*, char const*, int, bool) + 0x118 (0x149b2a1a6f08 in /home/charlie/anaconda3/envs/gpt-fast/lib/python3.10/site-packages/torch/lib/libc10_cuda.so)
frame #3: c10d::ProcessGroupNCCL::WorkNCCL::finishedGPUExecutionInternal() const + 0x56 (0x149adc7c5406 in /home/charlie/anaconda3/envs/gpt-fast/lib/python3.10/site-packages/torch/lib/libtorch_cuda.so)
frame #4: c10d::ProcessGroupNCCL::WorkNCCL::isCompleted() + 0xa0 (0x149adc7ca620 in /home/charlie/anaconda3/envs/gpt-fast/lib/python3.10/site-packages/torch/lib/libtorch_cuda.so)
frame #5: c10d::ProcessGroupNCCL::watchdogHandler() + 0x1da (0x149adc7d12da in /home/charlie/anaconda3/envs/gpt-fast/lib/python3.10/site-packages/torch/lib/libtorch_cuda.so)
frame #6: c10d::ProcessGroupNCCL::ncclCommWatchdog() + 0x10c (0x149adc7d371c in /home/charlie/anaconda3/envs/gpt-fast/lib/python3.10/site-packages/torch/lib/libtorch_cuda.so)
frame #7: <unknown function> + 0xd3b75 (0x149b2a4f0b75 in /home/charlie/anaconda3/envs/gpt-fast/bin/../lib/libstdc++.so.6)
frame #8: <unknown function> + 0x94ac3 (0x149b2b56bac3 in /lib/x86_64-linux-gnu/libc.so.6)
frame #9: <unknown function> + 0x126850 (0x149b2b5fd850 in /lib/x86_64-linux-gnu/libc.so.6)

Exception raised from ncclCommWatchdog at ../torch/csrc/distributed/c10d/ProcessGroupNCCL.cpp:1521 (most recent call first):
frame #0: c10::Error::Error(c10::SourceLocation, std::string) + 0x96 (0x149b2a0cbf86 in /home/charlie/anaconda3/envs/gpt-fast/lib/python3.10/site-packages/torch/lib/libc10.so)
frame #1: <unknown function> + 0xe5aa84 (0x149adc45ca84 in /home/charlie/anaconda3/envs/gpt-fast/lib/python3.10/site-packages/torch/lib/libtorch_cuda.so)
frame #2: <unknown function> + 0xd3b75 (0x149b2a4f0b75 in /home/charlie/anaconda3/envs/gpt-fast/bin/../lib/libstdc++.so.6)
frame #3: <unknown function> + 0x94ac3 (0x149b2b56bac3 in /lib/x86_64-linux-gnu/libc.so.6)
frame #4: <unknown function> + 0x126850 (0x149b2b5fd850 in /lib/x86_64-linux-gnu/libc.so.6)

W0920 09:14:25.378000 22940906227520 torch/distributed/elastic/multiprocessing/api.py:858] Sending process 966607 closing signal SIGTERM
W0920 09:14:25.379000 22940906227520 torch/distributed/elastic/multiprocessing/api.py:858] Sending process 966608 closing signal SIGTERM
W0920 09:14:25.379000 22940906227520 torch/distributed/elastic/multiprocessing/api.py:858] Sending process 966609 closing signal SIGTERM
W0920 09:14:25.379000 22940906227520 torch/distributed/elastic/multiprocessing/api.py:858] Sending process 966610 closing signal SIGTERM
W0920 09:14:25.380000 22940906227520 torch/distributed/elastic/multiprocessing/api.py:858] Sending process 966611 closing signal SIGTERM
W0920 09:14:25.380000 22940906227520 torch/distributed/elastic/multiprocessing/api.py:858] Sending process 966613 closing signal SIGTERM
W0920 09:14:25.380000 22940906227520 torch/distributed/elastic/multiprocessing/api.py:858] Sending process 966614 closing signal SIGTERM
E0920 09:14:26.673000 22940906227520 torch/distributed/elastic/multiprocessing/api.py:833] failed (exitcode: -6) local_rank: 5 (pid: 966612) of binary: /home/charlie/anaconda3/envs/gpt-fast/bin/python
Traceback (most recent call last):
  File "/home/charlie/anaconda3/envs/gpt-fast/bin/torchrun", line 8, in <module>
    sys.exit(main())
  File "/home/charlie/anaconda3/envs/gpt-fast/lib/python3.10/site-packages/torch/distributed/elastic/multiprocessing/errors/__init__.py", line 348, in wrapper
    return f(*args, **kwargs)
  File "/home/charlie/anaconda3/envs/gpt-fast/lib/python3.10/site-packages/torch/distributed/run.py", line 901, in main
    run(args)
  File "/home/charlie/anaconda3/envs/gpt-fast/lib/python3.10/site-packages/torch/distributed/run.py", line 892, in run
    elastic_launch(
  File "/home/charlie/anaconda3/envs/gpt-fast/lib/python3.10/site-packages/torch/distributed/launcher/api.py", line 133, in __call__
    return launch_agent(self._config, self._entrypoint, list(args))
  File "/home/charlie/anaconda3/envs/gpt-fast/lib/python3.10/site-packages/torch/distributed/launcher/api.py", line 264, in launch_agent
    raise ChildFailedError(
torch.distributed.elastic.multiprocessing.errors.ChildFailedError: 
=======================================================
benchmark.py FAILED
-------------------------------------------------------
Failures:
  <NO_OTHER_FAILURES>
-------------------------------------------------------
Root Cause (first observed failure):
[0]:
  time      : 2024-09-20_09:14:25
  host      : mk-xii-15.cloud.together.ai
  rank      : 5 (local_rank: 5)
  exitcode  : -6 (pid: 966612)
  error_file: <N/A>
  traceback : Signal 6 (SIGABRT) received by PID 966612
=======================================================
