flash_kv_decode is set to True
Using device=cuda
Loading model ...
GPTDense(
  (tok_embeddings): Embedding(128256, 4096)
  (layers): ModuleList(
    (0-31): 32 x DenseTransformerBlock(
      semi_compiled = False
      (attention): Attention(
        (wqkv): Linear(in_features=4096, out_features=6144, bias=False)
        (wo): Linear(in_features=4096, out_features=4096, bias=False)
      )
      (feed_forward): FeedForward(
        (w1): Linear(in_features=4096, out_features=28672, bias=False)
        (w2): Linear(in_features=14336, out_features=4096, bias=False)
      )
      (ffn_norm): RMSNorm()
      (attention_norm): RMSNorm()
    )
  )
  (norm): RMSNorm()
  (output): Linear(in_features=4096, out_features=128256, bias=False)
)
Time to load model: 1.21 seconds
/home/charlie/anaconda3/envs/gpt-fast/lib/python3.10/contextlib.py:103: FutureWarning: `torch.backends.cuda.sdp_kernel()` is deprecated. In the future, this context manager will be removed. Please see `torch.nn.attention.sdpa_kernel()` for the new context manager, with updated signature.
  self.gen = func(*args, **kwds)
Prefill latency: 2.096621800214052 sec
[rank0]:[E920 08:52:09.543354496 ProcessGroupNCCL.cpp:1515] [PG 0 (default_pg) Rank 0] Process group watchdog thread terminated with exception: CUDA error: an illegal memory access was encountered
CUDA kernel errors might be asynchronously reported at some other API call, so the stacktrace below might be incorrect.
For debugging consider passing CUDA_LAUNCH_BLOCKING=1
Compile with `TORCH_USE_CUDA_DSA` to enable device-side assertions.

Exception raised from c10_cuda_check_implementation at ../c10/cuda/CUDAException.cpp:43 (most recent call first):
frame #0: c10::Error::Error(c10::SourceLocation, std::string) + 0x96 (0x14feb1d77f86 in /home/charlie/anaconda3/envs/gpt-fast/lib/python3.10/site-packages/torch/lib/libc10.so)
frame #1: c10::detail::torchCheckFail(char const*, char const*, unsigned int, std::string const&) + 0x64 (0x14feb1d26d10 in /home/charlie/anaconda3/envs/gpt-fast/lib/python3.10/site-packages/torch/lib/libc10.so)
frame #2: c10::cuda::c10_cuda_check_implementation(int, char const*, char const*, int, bool) + 0x118 (0x14feb255ef08 in /home/charlie/anaconda3/envs/gpt-fast/lib/python3.10/site-packages/torch/lib/libc10_cuda.so)
frame #3: c10d::ProcessGroupNCCL::WorkNCCL::finishedGPUExecutionInternal() const + 0x56 (0x14fe643c5406 in /home/charlie/anaconda3/envs/gpt-fast/lib/python3.10/site-packages/torch/lib/libtorch_cuda.so)
frame #4: c10d::ProcessGroupNCCL::WorkNCCL::isCompleted() + 0xa0 (0x14fe643ca620 in /home/charlie/anaconda3/envs/gpt-fast/lib/python3.10/site-packages/torch/lib/libtorch_cuda.so)
frame #5: c10d::ProcessGroupNCCL::watchdogHandler() + 0x1da (0x14fe643d12da in /home/charlie/anaconda3/envs/gpt-fast/lib/python3.10/site-packages/torch/lib/libtorch_cuda.so)
frame #6: c10d::ProcessGroupNCCL::ncclCommWatchdog() + 0x10c (0x14fe643d371c in /home/charlie/anaconda3/envs/gpt-fast/lib/python3.10/site-packages/torch/lib/libtorch_cuda.so)
frame #7: <unknown function> + 0xd3b75 (0x14feb20f0b75 in /home/charlie/anaconda3/envs/gpt-fast/bin/../lib/libstdc++.so.6)
frame #8: <unknown function> + 0x94ac3 (0x14feb3251ac3 in /lib/x86_64-linux-gnu/libc.so.6)
frame #9: <unknown function> + 0x126850 (0x14feb32e3850 in /lib/x86_64-linux-gnu/libc.so.6)

terminate called after throwing an instance of 'c10::DistBackendError'
  what():  [PG 0 (default_pg) Rank 0] Process group watchdog thread terminated with exception: CUDA error: an illegal memory access was encountered
CUDA kernel errors might be asynchronously reported at some other API call, so the stacktrace below might be incorrect.
For debugging consider passing CUDA_LAUNCH_BLOCKING=1
Compile with `TORCH_USE_CUDA_DSA` to enable device-side assertions.

Exception raised from c10_cuda_check_implementation at ../c10/cuda/CUDAException.cpp:43 (most recent call first):
frame #0: c10::Error::Error(c10::SourceLocation, std::string) + 0x96 (0x14feb1d77f86 in /home/charlie/anaconda3/envs/gpt-fast/lib/python3.10/site-packages/torch/lib/libc10.so)
frame #1: c10::detail::torchCheckFail(char const*, char const*, unsigned int, std::string const&) + 0x64 (0x14feb1d26d10 in /home/charlie/anaconda3/envs/gpt-fast/lib/python3.10/site-packages/torch/lib/libc10.so)
frame #2: c10::cuda::c10_cuda_check_implementation(int, char const*, char const*, int, bool) + 0x118 (0x14feb255ef08 in /home/charlie/anaconda3/envs/gpt-fast/lib/python3.10/site-packages/torch/lib/libc10_cuda.so)
frame #3: c10d::ProcessGroupNCCL::WorkNCCL::finishedGPUExecutionInternal() const + 0x56 (0x14fe643c5406 in /home/charlie/anaconda3/envs/gpt-fast/lib/python3.10/site-packages/torch/lib/libtorch_cuda.so)
frame #4: c10d::ProcessGroupNCCL::WorkNCCL::isCompleted() + 0xa0 (0x14fe643ca620 in /home/charlie/anaconda3/envs/gpt-fast/lib/python3.10/site-packages/torch/lib/libtorch_cuda.so)
frame #5: c10d::ProcessGroupNCCL::watchdogHandler() + 0x1da (0x14fe643d12da in /home/charlie/anaconda3/envs/gpt-fast/lib/python3.10/site-packages/torch/lib/libtorch_cuda.so)
frame #6: c10d::ProcessGroupNCCL::ncclCommWatchdog() + 0x10c (0x14fe643d371c in /home/charlie/anaconda3/envs/gpt-fast/lib/python3.10/site-packages/torch/lib/libtorch_cuda.so)
frame #7: <unknown function> + 0xd3b75 (0x14feb20f0b75 in /home/charlie/anaconda3/envs/gpt-fast/bin/../lib/libstdc++.so.6)
frame #8: <unknown function> + 0x94ac3 (0x14feb3251ac3 in /lib/x86_64-linux-gnu/libc.so.6)
frame #9: <unknown function> + 0x126850 (0x14feb32e3850 in /lib/x86_64-linux-gnu/libc.so.6)

Exception raised from ncclCommWatchdog at ../torch/csrc/distributed/c10d/ProcessGroupNCCL.cpp:1521 (most recent call first):
frame #0: c10::Error::Error(c10::SourceLocation, std::string) + 0x96 (0x14feb1d77f86 in /home/charlie/anaconda3/envs/gpt-fast/lib/python3.10/site-packages/torch/lib/libc10.so)
frame #1: <unknown function> + 0xe5aa84 (0x14fe6405ca84 in /home/charlie/anaconda3/envs/gpt-fast/lib/python3.10/site-packages/torch/lib/libtorch_cuda.so)
frame #2: <unknown function> + 0xd3b75 (0x14feb20f0b75 in /home/charlie/anaconda3/envs/gpt-fast/bin/../lib/libstdc++.so.6)
frame #3: <unknown function> + 0x94ac3 (0x14feb3251ac3 in /lib/x86_64-linux-gnu/libc.so.6)
frame #4: <unknown function> + 0x126850 (0x14feb32e3850 in /lib/x86_64-linux-gnu/libc.so.6)

E0920 08:52:10.082000 22461296695104 torch/distributed/elastic/multiprocessing/api.py:833] failed (exitcode: -6) local_rank: 0 (pid: 959519) of binary: /home/charlie/anaconda3/envs/gpt-fast/bin/python
Traceback (most recent call last):
  File "/home/charlie/anaconda3/envs/gpt-fast/bin/torchrun", line 8, in <module>
    sys.exit(main())
  File "/home/charlie/anaconda3/envs/gpt-fast/lib/python3.10/site-packages/torch/distributed/elastic/multiprocessing/errors/__init__.py", line 348, in wrapper
    return f(*args, **kwargs)
  File "/home/charlie/anaconda3/envs/gpt-fast/lib/python3.10/site-packages/torch/distributed/run.py", line 901, in main
    run(args)
  File "/home/charlie/anaconda3/envs/gpt-fast/lib/python3.10/site-packages/torch/distributed/run.py", line 892, in run
    elastic_launch(
  File "/home/charlie/anaconda3/envs/gpt-fast/lib/python3.10/site-packages/torch/distributed/launcher/api.py", line 133, in __call__
    return launch_agent(self._config, self._entrypoint, list(args))
  File "/home/charlie/anaconda3/envs/gpt-fast/lib/python3.10/site-packages/torch/distributed/launcher/api.py", line 264, in launch_agent
    raise ChildFailedError(
torch.distributed.elastic.multiprocessing.errors.ChildFailedError: 
=======================================================
benchmark.py FAILED
-------------------------------------------------------
Failures:
  <NO_OTHER_FAILURES>
-------------------------------------------------------
Root Cause (first observed failure):
[0]:
  time      : 2024-09-20_08:52:10
  host      : mk-xii-15.cloud.together.ai
  rank      : 0 (local_rank: 0)
  exitcode  : -6 (pid: 959519)
  error_file: <N/A>
  traceback : Signal 6 (SIGABRT) received by PID 959519
=======================================================
