W1001 20:35:26.179000 23294685697856 torch/distributed/run.py:779] 
W1001 20:35:26.179000 23294685697856 torch/distributed/run.py:779] *****************************************
W1001 20:35:26.179000 23294685697856 torch/distributed/run.py:779] Setting OMP_NUM_THREADS environment variable for each process to be 1 in default, to avoid your system being overloaded, please further tune the variable for optimal performance in your application as needed. 
W1001 20:35:26.179000 23294685697856 torch/distributed/run.py:779] *****************************************
flash_kv_decode is set to True
Using device=cuda
Loading model ...
GPTEnsemble(
  (tok_embeddings): Embedding(128256, 4096)
  (layers): ModuleList(
    (0-31): 32 x EnsembleTransformerBlock(
      semi_compiled = False
      (attention): Attention(
        (wqkv): Linear(in_features=4096, out_features=3072, bias=False)
        (wo): Linear(in_features=2048, out_features=4096, bias=False)
      )
      (feed_forward): FeedForward(
        (w1): Linear(in_features=4096, out_features=14336, bias=False)
        (w2): Linear(in_features=7168, out_features=4096, bias=False)
      )
      (ffn_norm): RMSNorm()
      (attention_norm): RMSNorm()
    )
  )
  (norm): RMSNorm()
  (output): Linear(in_features=4096, out_features=128256, bias=False)
)
Time to load model: 1.08 seconds
[rank1]: Traceback (most recent call last):
[rank1]:   File "/home/charlie/skip-residual/gpt-fast/benchmark.py", line 490, in <module>
[rank1]:     main(
[rank1]:   File "/home/charlie/skip-residual/gpt-fast/benchmark.py", line 364, in main
[rank1]:     decode_graph, static_cur_token, static_decode_input_pos, static_next_token_decode = get_cuda_graphs_for_decode(
[rank1]:   File "/home/charlie/anaconda3/envs/gpt-fast/lib/python3.10/site-packages/torch/utils/_contextlib.py", line 116, in decorate_context
[rank1]:     return func(*args, **kwargs)
[rank1]:   File "/home/charlie/skip-residual/gpt-fast/benchmark.py", line 291, in get_cuda_graphs_for_decode
[rank1]:     decode_one_token(model, static_cur_token, static_input_pos, **sampling_kwargs)
[rank1]:   File "/home/charlie/skip-residual/gpt-fast/benchmark.py", line 85, in decode_one_token
[rank1]:     logits = model(x, input_pos)
[rank1]:   File "/home/charlie/anaconda3/envs/gpt-fast/lib/python3.10/site-packages/torch/nn/modules/module.py", line 1553, in _wrapped_call_impl
[rank1]:     return self._call_impl(*args, **kwargs)
[rank1]:   File "/home/charlie/anaconda3/envs/gpt-fast/lib/python3.10/site-packages/torch/nn/modules/module.py", line 1562, in _call_impl
[rank1]:     return forward_call(*args, **kwargs)
[rank1]:   File "/home/charlie/skip-residual/gpt-fast/gpt_fast/gpt_ensemble_TP.py", line 140, in forward
[rank1]:     x = layer(x, input_pos, freqs_cis, mask)
[rank1]:   File "/home/charlie/anaconda3/envs/gpt-fast/lib/python3.10/site-packages/torch/nn/modules/module.py", line 1553, in _wrapped_call_impl
[rank1]:     return self._call_impl(*args, **kwargs)
[rank1]:   File "/home/charlie/anaconda3/envs/gpt-fast/lib/python3.10/site-packages/torch/nn/modules/module.py", line 1562, in _call_impl
[rank1]:     return forward_call(*args, **kwargs)
[rank1]:   File "/home/charlie/skip-residual/gpt-fast/gpt_fast/gpt_ensemble_TP.py", line 206, in forward
[rank1]:     x = self.attention(self.attention_norm(x), freqs_cis, mask, input_pos)
[rank1]:   File "/home/charlie/anaconda3/envs/gpt-fast/lib/python3.10/site-packages/torch/nn/modules/module.py", line 1553, in _wrapped_call_impl
[rank1]:     return self._call_impl(*args, **kwargs)
[rank1]:   File "/home/charlie/anaconda3/envs/gpt-fast/lib/python3.10/site-packages/torch/nn/modules/module.py", line 1562, in _call_impl
[rank1]:     return forward_call(*args, **kwargs)
[rank1]:   File "/home/charlie/skip-residual/gpt-fast/gpt_fast/utils.py", line 189, in forward
[rank1]:     q = apply_rotary_emb(q, freqs_cis)
[rank1]:   File "/home/charlie/skip-residual/gpt-fast/gpt_fast/utils.py", line 125, in apply_rotary_emb
[rank1]:     return x_out2.type_as(x)
[rank1]: RuntimeError: CUDA error: an illegal memory access was encountered
[rank1]: CUDA kernel errors might be asynchronously reported at some other API call, so the stacktrace below might be incorrect.
[rank1]: For debugging consider passing CUDA_LAUNCH_BLOCKING=1
[rank1]: Compile with `TORCH_USE_CUDA_DSA` to enable device-side assertions.

[rank0]: Traceback (most recent call last):
[rank0]:   File "/home/charlie/skip-residual/gpt-fast/benchmark.py", line 490, in <module>
[rank0]:     main(
[rank0]:   File "/home/charlie/skip-residual/gpt-fast/benchmark.py", line 364, in main
[rank0]:     decode_graph, static_cur_token, static_decode_input_pos, static_next_token_decode = get_cuda_graphs_for_decode(
[rank0]:   File "/home/charlie/anaconda3/envs/gpt-fast/lib/python3.10/site-packages/torch/utils/_contextlib.py", line 116, in decorate_context
[rank0]:     return func(*args, **kwargs)
[rank0]:   File "/home/charlie/skip-residual/gpt-fast/benchmark.py", line 291, in get_cuda_graphs_for_decode
[rank0]:     decode_one_token(model, static_cur_token, static_input_pos, **sampling_kwargs)
[rank0]:   File "/home/charlie/skip-residual/gpt-fast/benchmark.py", line 85, in decode_one_token
[rank0]:     logits = model(x, input_pos)
[rank0]:   File "/home/charlie/anaconda3/envs/gpt-fast/lib/python3.10/site-packages/torch/nn/modules/module.py", line 1553, in _wrapped_call_impl
[rank0]:     return self._call_impl(*args, **kwargs)
[rank0]:   File "/home/charlie/anaconda3/envs/gpt-fast/lib/python3.10/site-packages/torch/nn/modules/module.py", line 1562, in _call_impl
[rank0]:     return forward_call(*args, **kwargs)
[rank0]:   File "/home/charlie/skip-residual/gpt-fast/gpt_fast/gpt_ensemble_TP.py", line 140, in forward
[rank0]:     x = layer(x, input_pos, freqs_cis, mask)
[rank0]:   File "/home/charlie/anaconda3/envs/gpt-fast/lib/python3.10/site-packages/torch/nn/modules/module.py", line 1553, in _wrapped_call_impl
[rank0]:     return self._call_impl(*args, **kwargs)
[rank0]:   File "/home/charlie/anaconda3/envs/gpt-fast/lib/python3.10/site-packages/torch/nn/modules/module.py", line 1562, in _call_impl
[rank0]:     return forward_call(*args, **kwargs)
[rank0]:   File "/home/charlie/skip-residual/gpt-fast/gpt_fast/gpt_ensemble_TP.py", line 206, in forward
[rank0]:     x = self.attention(self.attention_norm(x), freqs_cis, mask, input_pos)
[rank0]:   File "/home/charlie/anaconda3/envs/gpt-fast/lib/python3.10/site-packages/torch/nn/modules/module.py", line 1553, in _wrapped_call_impl
[rank0]:     return self._call_impl(*args, **kwargs)
[rank0]:   File "/home/charlie/anaconda3/envs/gpt-fast/lib/python3.10/site-packages/torch/nn/modules/module.py", line 1562, in _call_impl
[rank0]:     return forward_call(*args, **kwargs)
[rank0]:   File "/home/charlie/skip-residual/gpt-fast/gpt_fast/utils.py", line 189, in forward
[rank0]:     q = apply_rotary_emb(q, freqs_cis)
[rank0]:   File "/home/charlie/skip-residual/gpt-fast/gpt_fast/utils.py", line 125, in apply_rotary_emb
[rank0]:     return x_out2.type_as(x)
[rank0]: RuntimeError: CUDA error: an illegal memory access was encountered
[rank0]: CUDA kernel errors might be asynchronously reported at some other API call, so the stacktrace below might be incorrect.
[rank0]: For debugging consider passing CUDA_LAUNCH_BLOCKING=1
[rank0]: Compile with `TORCH_USE_CUDA_DSA` to enable device-side assertions.

W1001 20:35:36.207000 23294685697856 torch/distributed/elastic/multiprocessing/api.py:858] Sending process 2016215 closing signal SIGTERM
E1001 20:35:36.374000 23294685697856 torch/distributed/elastic/multiprocessing/api.py:833] failed (exitcode: 1) local_rank: 1 (pid: 2016216) of binary: /home/charlie/anaconda3/envs/gpt-fast/bin/python
Traceback (most recent call last):
  File "/home/charlie/anaconda3/envs/gpt-fast/bin/torchrun", line 8, in <module>
    sys.exit(main())
  File "/home/charlie/anaconda3/envs/gpt-fast/lib/python3.10/site-packages/torch/distributed/elastic/multiprocessing/errors/__init__.py", line 348, in wrapper
    return f(*args, **kwargs)
  File "/home/charlie/anaconda3/envs/gpt-fast/lib/python3.10/site-packages/torch/distributed/run.py", line 901, in main
    run(args)
  File "/home/charlie/anaconda3/envs/gpt-fast/lib/python3.10/site-packages/torch/distributed/run.py", line 892, in run
    elastic_launch(
  File "/home/charlie/anaconda3/envs/gpt-fast/lib/python3.10/site-packages/torch/distributed/launcher/api.py", line 133, in __call__
    return launch_agent(self._config, self._entrypoint, list(args))
  File "/home/charlie/anaconda3/envs/gpt-fast/lib/python3.10/site-packages/torch/distributed/launcher/api.py", line 264, in launch_agent
    raise ChildFailedError(
torch.distributed.elastic.multiprocessing.errors.ChildFailedError: 
============================================================
benchmark.py FAILED
------------------------------------------------------------
Failures:
  <NO_OTHER_FAILURES>
------------------------------------------------------------
Root Cause (first observed failure):
[0]:
  time      : 2024-10-01_20:35:36
  host      : mk-xii-19.cloud.together.ai
  rank      : 1 (local_rank: 1)
  exitcode  : 1 (pid: 2016216)
  error_file: <N/A>
  traceback : To enable traceback see: https://pytorch.org/docs/stable/elastic/errors.html
============================================================
